Workbook
Name Aktuell: #REF!
Name Projeziert: #REF!

Sheet FIM IA 2
X4: Department of Finance
X5: © Teaching Center
E8: Involving Activity 2: Performance Attribution and Evaluation
E12: In der IA 2 geht es darum, die realisierte Rendite deines Portfolios zu analysieren und zu verstehen. Zudem sollst du herausfinden, welche Faktoren bzw. Positionen die wichtigsten Renditetreiber deines Portfolios waren. Bei der Beantwortung der untenstehenden Fragen solltest du dich auf dein persönliches Portfolio aus der IA 1 beziehen und mit denselben Portfoliogewichten arbeiten. Die für alle Berechnungen benötigten Daten findest du in der Lasche „Daten“.
E17: Name | F17: Ivan Camilo Dorado Dorado
E20: Frage 1
E21: Bestimme für alle Anleihenpositionen sowohl die realisierte Rendite über den gesamten Betrachtungszeitraum als auch die daraus abgeleitete annualisierte Rendite.
E23: ISIN | F23: Emittent | G23: Ticker | H23: Land | I23: Verfall | J23: Coupon | K23: YTM | L23: Rating | M23: Kredit-spread | N23: Mod. Duration | O23: PreisClean | P23: Währung | Q23: Sektor | R23: Kapitalstruktur | S23: Callable | T23: Nachhaltig | U23: Deine Gewichtung | V23: Realisierte Rendite | W23: Annualisierte Rendite
E24: US037833DB33 | F24: APPLE INC | G24: AAPL | H24: US | I24: 2027-09-12 | J24: 2.9 | K24: 0.036 | L24: AA+ | M24: 0.0014 | N24: 1.91 | O24: 98.65 | P24: USD | Q24: Technology Hardware, Storage and Peripherals | R24: Senior Unsecured | S24: true | T24: false | U24: 0 | V24: ='Work with data'!B111 -> 0.0029658393 | W24: =(1+V24)^(365/(Daten!$E$49-Daten!$E$17))-1 -> 0.023264999
E25: US05253JB751 | F25: AUSTRALIA AND NEW ZEALAND BANKING MTN | G25: ANZ | H25: AU | I25: 2028-06-18 | J25: 4.36 | K25: 0.0385 | L25: AA- | M25: 0.0041 | N25: 2.58 | O25: 101.35 | P25: USD | Q25: Banks | R25: Senior Unsecured | S25: false | T25: false | U25: 0.1 | V25: ='Work with data'!B112 -> 0.004989743 | W25: =(1+V25)^(365/(Daten!$E$49-Daten!$E$17))-1 -> 0.039410552
E26: XS2058948451 | F26: BAHRAIN (KINGDOM OF) MTN RegS | G26: BHRAIN | H26: BH | I26: 2031-09-30 | J26: 5.63 | K26: 0.0575 | L26: B+ | M26: 0.0222 | N26: 4.96 | O26: 99.34 | P26: USD | Q26: Sovereign | R26: Senior Unsecured | S26: false | T26: false | U26: 0 | V26: ='Work with data'!B113 -> 0.0017644277 | W26: =(1+V26)^(365/(Daten!$E$49-Daten!$E$17))-1 -> 0.013784539
E27: US056752AR92 | F27: BAIDU INC | G27: BIDU | H27: CN | I27: 2030-04-07 | J27: 3.42 | K27: 0.0411 | L27: A | M27: 0.0063 | N27: 4.13 | O27: 97.16 | P27: USD | Q27: IT Services | R27: Senior Unsecured | S27: true | T27: false | U27: 0.1 | V27: ='Work with data'!B114 -> 0.0054585559 | W27: =(1+V27)^(365/(Daten!$E$49-Daten!$E$17))-1 -> 0.043181977
E28: US06051GGC78 | F28: BANK OF AMERICA CORP MTN | G28: BAC | H28: US | I28: 2027-11-25 | J28: 4.18 | K28: 0.0412 | L28: A- | M28: 0.0069 | N28: 2.08 | O28: 100.09 | P28: USD | Q28: Banks | R28: Subordinated | S28: true | T28: false | U28: 0 | V28: ='Work with data'!B115 -> 0.0048407919 | W28: =(1+V28)^(365/(Daten!$E$49-Daten!$E$17))-1 -> 0.038214786
E29: US097023CV59 | F29: BOEING CO | G29: BA | H29: US | I29: 2040-05-01 | J29: 5.71 | K29: 0.055 | L29: BBB- | M29: 0.0145 | N29: 9.72 | O29: 102.03 | P29: USD | Q29: Aerospace and Defense | R29: Senior Unsecured | S29: true | T29: false | U29: 0 | V29: ='Work with data'!B116 -> 0.0031078074 | W29: =(1+V29)^(365/(Daten!$E$49-Daten!$E$17))-1 -> 0.024390369
E30: US172967KU42 | F30: CITIGROUP INC | G30: C | H30: US | I30: 2028-07-25 | J30: 4.13 | K30: 0.041 | L30: BBB+ | M30: 0.0067 | N30: 2.69 | O30: 100.04 | P30: USD | Q30: Banks | R30: Subordinated | S30: false | T30: false | U30: 0.1 | V30: ='Work with data'!B117 -> 0.0038123479 | W30: =(1+V30)^(365/(Daten!$E$49-Daten!$E$17))-1 -> 0.02999118
E31: US126650EB25 | F31: CVS HEALTH CORP | G31: CVS | H31: US | I31: 2029-06-01 | J31: 5.4 | K31: 0.043 | L31: BBB | M31: 0.0088 | N31: 3.33 | O31: 103.71 | P31: USD | Q31: Health Care Providers and Services | R31: Senior Unsecured | S31: true | T31: false | U31: 0 | V31: ='Work with data'!B118 -> 0.0057485178 | W31: =(1+V31)^(365/(Daten!$E$49-Daten!$E$17))-1 -> 0.045520575
E32: US247361ZN12 | F32: DELTA AIR LINES INC | G32: DAL | H32: US | I32: 2028-04-19 | J32: 4.38 | K32: 0.0428 | L32: BBB- | M32: 0.0084 | N32: 2.41 | O32: 100.15 | P32: USD | Q32: Airlines | R32: Senior Unsecured | S32: true | T32: false | U32: 0 | V32: ='Work with data'!B119 -> 0.0041354866 | W32: =(1+V32)^(365/(Daten!$E$49-Daten!$E$17))-1 -> 0.032568914
E33: XS2079842642 | F33: EGYPT (ARAB REPUBLIC OF) MTN RegS | G33: EGYPT | H33: EG | I33: 2032-01-15 | J33: 7.05 | K33: 0.0825 | L33: B- | M33: 0.0472 | N33: 4.94 | O33: 94.15 | P33: USD | Q33: Sovereign | R33: Senior Unsecured | S33: false | T33: false | U33: 0 | V33: ='Work with data'!B120 -> 0.02376503 | W33: =(1+V33)^(365/(Daten!$E$49-Daten!$E$17))-1 -> 0.20009334
E34: XS2539374673 | F34: FIRST ABU DHABI BANK PJSC MTN RegS | G34: FABUH | H34: AE | I34: 2027-10-13 | J34: 5.13 | K34: 0.0415 | L34: AA- | M34: 0.0069 | N34: 1.94 | O34: 101.94 | P34: USD | Q34: Banks | R34: Senior Unsecured | S34: false | T34: false | U34: 0 | V34: ='Work with data'!B121 -> 0.0057271822 | W34: =(1+V34)^(365/(Daten!$E$49-Daten!$E$17))-1 -> 0.045348344
E35: US345370DA55 | F35: FORD MOTOR COMPANY | G35: F | H35: US | I35: 2032-02-12 | J35: 3.25 | K35: 0.0575 | L35: BBB- | M35: 0.0215 | N35: 5.63 | O35: 86.76 | P35: USD | Q35: Automobiles | R35: Senior Unsecured | S35: true | T35: false | U35: 0 | V35: ='Work with data'!B122 -> 0.000956574 | W35: =(1+V35)^(365/(Daten!$E$49-Daten!$E$17))-1 -> 0.0074527971
... E73: US961214FC22 | F73: WESTPAC BANKING CORP | G73: WSTP | H73: AU | I73: 2027-08-26 | J73: 4.04 | K73: 0.0376 | L73: AA- | M73: 0.003 | N73: 1.88 | O73: 100.54 | P73: USD | Q73: Banks | R73: Senior Unsecured | S73: false | T73: false | U73: 0 | V73: ='Work with data'!B160 -> 0.0044004887 | W73: =(1+V73)^(365/(Daten!$E$49-Daten!$E$17))-1 -> 0.034687074
E76: Frage 2
E77: Berechne die zentralen Eigenschaften deines Portfolios (unter Verwendung deiner spezifischen Portfoliogewichte) sowie eines gleichgewichteten Portfolios, das im Folgenden als Benchmark dient.
F79: Portfolio | H79: Benchmark | L79: Relativ
E81: Anzahl Titel | F81: 10 | H81: =COUNTA(Daten!F16:BC16) -> 50 | L81: =F81/H81 -> 0.2
E83: Ø Coupon | F83: =AVERAGE(J25,J27,J30,J36,J47,J49,J54,J59,J65,J66)/100 -> 0.04654 | H83: =AVERAGE(J24:J73)/100 -> 0.048236 | L83: =F83/H83 -> 0.96483954
E85: Ø Restlaufzeit | F85: =AVERAGE('Work with data'!I37:I46) -> 6.8172603 | H85: ='Work with data'!I161 -> 6.1575342 | L85: =F85/H85 -> 1.1071413
E87: Mod. Duration | F87: ='Work with data'!G47 -> 5.765 | H87: =AVERAGE(N24:N73) -> 4.819 | L87: =F87/H87 -> 1.1963063
E89: Ø Verfallsrendite | F89: ='Work with data'!E47 -> 0.04309 | H89: =AVERAGE(K24:K73) -> 0.047996 | L89: =F89/H89 -> 0.89778315
E91: Ø Rating | F91: ='Work with data'!A56 -> A | H91: ='Work with data'!A57 -> A- | L91: A bis A-
E93: Ø Kreditspread | F93: ='Work with data'!F47 -> 0.00656 | H93: =AVERAGE(M24:M73) -> 0.01239 | L93: =F93/H93 -> 0.52945924
E95: DTS | F95: =SUMPRODUCT('Work with data'!F37:F46,'Work with data'!G37:G46)/10 -> 0.0383659 | H95: =SUMPRODUCT(M24:M73,N24:N73)/COUNTA(F24:F73) -> 0.06602718 | L95: =F95/H95 -> 0.58106222
E97: %-Anteil HY Bonds | F97: 0 | H97: =SUM('Work with data'!C61:C72)/'Work with data'!C73 -> 0.12 | L97: =F97-H97 -> -0.12
E100: Frage 3
E101: Berechne die historische Performance deines Portfolios, die Performance der Benchmark sowie die daraus resultierende Überrendite deines Portfolios gegenüber der Benchmark. Der Betrachtungszeitraum umfasst den 01.10.2025 bis 17.11.2025. Die hierfür benötigten Daten findest du in der Lasche „Daten“. Berechne zusätzlich die wichtigsten Performancekennzahlen, um die Resultate besser einordnen zu können. Nimm für die Berechnungen einen risikolosen Zinssatz von 0.25% p.a. an.
F103: Portfolio | H103: Benchmark | L103: Relativ
E105: Rendite | F105: ='Work with data'!B47 -> 0.0027026617 | H105: ='Work with data'!B161 -> 0.0036800932 | L105: =F105-H105 -> -0.00097743148
E107: Rendite (annualisiert) | F107: =(1+F105)^(365/(Daten!$E$49-Daten!$E$17))-1 -> 0.021181657 | H107: =(1+H105)^(365/(Daten!$E$49-Daten!$E$17))-1 -> 0.02893778 | L107: =F107-H107 -> -0.0077561227
E109: Stabw | F109: =_xlfn.STDEV.S('Work with data'!K2:K33) -> 0.00065066374 | H109: =_xlfn.STDEV.S('Work with data'!AY76:AY107) -> 0.00051533705
E111: Stabw (annualisiert) | F111: =F109*SQRT(252) -> 0.010328967 | H111: =H109*SQRT(252) -> 0.008180722
...

Sheet Daten
BC4: Department of Finance
BC5: © Teaching Center
E8: Involving Activity 2: Performance Attribution and Evaluation
E12: Nachfolgend findest du die Total-Return-Kursdaten der Anleihen in deinem Portfolio. Diese Total-Return-Serien beinhalten sowohl Preisveränderungen als auch Couponzahlungen und können daher direkt zur Berechnung der Performance der jeweiligen Anleihen verwendet werden.
E15: ISIN | F15: US037833DB33 | G15: US05253JB751 | H15: XS2058948451 | I15: US056752AR92 | J15: US06051GGC78 | K15: US097023CV59 | L15: US172967KU42 | M15: US126650EB25 | N15: US247361ZN12 | O15: XS2079842642 | P15: XS2539374673 | Q15: US345370DA55 | R15: US36962GXZ26 | S15: US37045VAY65 | T15: US42824CBT53 | U15: US438127AF94 | V15: US404280EX36 | W15: US455780DQ66 | X15: US456837BS18 | Y15: US458140CG35 | Z15: US500630EG96 | AA15: USY5257YAL12 | AB15: US539439AQ24 | AC15: US539830CA58 | AD15: US30303M8H84 | AE15: US59156RAM07 | AF15: US91087BAH33 | AG15: US606822DL51 | AH15: US674599ED34 | AI15: XS1932866079 | AJ15: US68389XAV73 | AK15: XS1729875598 | AL15: US71654QDF63 | AM15: US718286BD89 | AN15: US718547AY80 | AO15: US78016HZQ63 | AP15: XS2262853265 | AQ15: XS1619155564 | AR15: US836205BC70 | AS15: USG84228FZ63 | AT15: US88032XAG97 | AU15: US91282CNC19 | AV15: US91282CLF67 | AW15: US91282CHT18 | AX15: US91282CCS89 | AY15: US91282CKX82 | AZ15: US91282CJF95 | BA15: US9128284V99 | BB15: US90353TAP57 | BC15: US961214FC22
E16: Ticker | F16: =VLOOKUP(F15,'FIM IA 2'!$E$23:$F$73,2,FALSE) -> APPLE INC | G16: =VLOOKUP(G15,'FIM IA 2'!$E$23:$F$73,2,FALSE) -> AUSTRALIA AND NEW ZEALAND BANKING MTN | H16: =VLOOKUP(H15,'FIM IA 2'!$E$23:$F$73,2,FALSE) -> BAHRAIN (KINGDOM OF) MTN RegS | I16: =VLOOKUP(I15,'FIM IA 2'!$E$23:$F$73,2,FALSE) -> BAIDU INC | J16: =VLOOKUP(J15,'FIM IA 2'!$E$23:$F$73,2,FALSE) -> BANK OF AMERICA CORP MTN | K16: =VLOOKUP(K15,'FIM IA 2'!$E$23:$F$73,2,FALSE) -> BOEING CO | L16: =VLOOKUP(L15,'FIM IA 2'!$E$23:$F$73,2,FALSE) -> CITIGROUP INC | M16: =VLOOKUP(M15,'FIM IA 2'!$E$23:$F$73,2,FALSE) -> CVS HEALTH CORP | ... BC16: =VLOOKUP(BC15,'FIM IA 2'!$E$23:$F$73,2,FALSE) -> WESTPAC BANKING CORP
E17: 45931 | F17: 100 | G17: 100 | H17: 100 | I17: 100 | J17: 100 | K17: 100 | L17: 100 | M17: 100 | N17: 100 | O17: 100 | P17: 100 | Q17: 100 | R17: 100 | S17: 100 | T17: 100 | U17: 100 | V17: 100 | W17: 100 | X17: 100 | Y17: 100 | Z17: 100 | AA17: 100 | AB17: 100 | AC17: 100 | AD17: 100 | AE17: 100 | AF17: 100 | AG17: 100 | AH17: 100 | AI17: 100 | AJ17: 100 | AK17: 100 | AL17: 100 | AM17: 100 | AN17: 100 | AO17: 100 | AP17: 100 | AQ17: 100 | AR17: 100 | AS17: 100 | AT17: 100 | AU17: 100 | AV17: 100 | AW17: 100 | AX17: 100 | AY17: 100 | AZ17: 100 | BA17: 100 | BB17: 100 | BC17: 100
E18: 45932 | F18: 100.0072 | G18: 100.01744 | H18: 100.04845 | I18: 100.06736 | J18: 100.01672 | K18: 100.1117 | L18: 100.06423 | M18: 100.04256 | N18: 99.969845 | O18: 100.25257 | P18: 100.02052 | Q18: 100.112 | R18: 100.08406 | S18: 100.05099 | T18: 100.02682 | U18: 100.10191 | V18: 100.10514 | W18: 100.09145 | X18: 100.12221 | Y18: 100.03773 | Z18: 100.01852 | AA18: 100.08215 | AB18: 100.01428 | AC18: 100.08327 | AD18: 100.05989 | AE18: 100.09551 | AF18: 100.013 | AG18: 100.10494 | AH18: 100.1477 | AI18: 100.08021 | AJ18: 100.08501 | AK18: 100.00576 | AL18: 99.922003 | AM18: 100.02552 | AN18: 100.09836 | AO18: 100.08723 | AP18: 100.04265 | AQ18: 101.1404 | AR18: 100.10071 | AS18: 100.0321 | AT18: 100.03628 | AU18: 100.017 | AV18: 100.01552 | AW18: 100.01552 | AX18: 100.005 | AY18: 100.017 | AZ18: 100.01952 | BA18: 100.01152 | BB18: 100.10128 | BC18: 100.0032
E19: 45933 | F19: 100.00117 | G19: 100.00055 | H19: 100.05801 | I19: 100.03629 | J19: 100.02477 | K19: 99.998936 | L19: 100.02868 | M19: 100.00544 | N19: 99.970016 | O19: 100.37945 | P19: 100.08365 | Q19: 100.06557 | R19: 100.00442 | S19: 100.00536 | T19: 100.0062 | U19: 100.13178 | V19: 100.075 | W19: 100.11397 | X19: 100.04832 | Y19: 100.05854 | Z19: 100.09044 | AA19: 100.07606 | AB19: 100.01538 | AC19: 100.02509 | AD19: 100.00851 | AE19: 100.00507 | AF19: 100.07495 | AG19: 100.0325 | AH19: 100.23481 | AI19: 100.04101 | AJ19: 99.930094 | AK19: 100.09854 | AL19: 100.36586 | AM19: 100.09864 | AN19: 100.00017 | AO19: 100.01891 | AP19: 100.0853 | AQ19: 101.48021 | AR19: 100.16284 | AS19: 99.975657 | AT19: 100.07693 | AU19: 100.06787 | AV19: 100.0653 | AW19: 100.06506 | AX19: 100.11762 | AY19: 100.02253 | AZ19: 100.09308 | BA19: 100.00977 | BB19: 100.0643 | BC19: 99.997746
E20: 45936 | F20: 100.00396 | G20: 99.996514 | H20: 99.993981 | I20: 100.0007 | J20: 100.01546 | K20: 99.885874 | L20: 100.0148 | M20: 99.989261 | N20: 100.00487 | O20: 100.43464 | P20: 100.04876 | Q20: 100.07858 | R20: 99.878708 | S20: 100.01855 | T20: 99.98986 | U20: 100.04702 | V20: 99.974903 | W20: 100.12788 | X20: 99.928214 | Y20: 99.977587 | Z20: 100.08504 | AA20: 100.12883 | AB20: 100.00767 | AC20: 99.923806 | AD20: 99.957051 | AE20: 99.922532 | AF20: 100.08155 | AG20: 99.976463 | AH20: 100.18461 | AI20: 100.01884 | AJ20: 99.8293 | AK20: 100.08255 | AL20: 100.28834 | AM20: 100.05077 | AN20: 99.923675 | AO20: 99.929359 | AP20: 100.00771 | AQ20: 101.58265 | AR20: 100.11344 | AS20: 99.951348 | AT20: 100.08697 | AU20: 99.866553 | AV20: 99.883151 | AW20: 99.901392 | AX20: 99.98929 | AY20: 99.966376 | AZ20: 100.05519 | BA20: 99.981457 | BB20: 99.970938 | BC20: 100.00093
E21: 45937 | F21: 100.03759 | G21: 100.07833 | H21: 100.05112 | I21: 100.05021 | J21: 100.04954 | K21: 99.96813 | L21: 100.06172 | M21: 100.05283 | N21: 99.987689 | O21: 100.34627 | P21: 100.05649 | Q21: 100.07177 | R21: 99.99344 | S21: 100.09479 | T21: 100.03396 | U21: 100.20409 | V21: 100.05147 | W21: 100.14611 | X21: 100.08404 | Y21: 100.05349 | Z21: 100.09033 | AA21: 100.24878 | AB21: 100.03514 | AC21: 100.02008 | AD21: 99.990274 | AE21: 100.00607 | AF21: 100.07168 | AG21: 100.08567 | AH21: 100.2637 | AI21: 100.09058 | AJ21: 99.769233 | AK21: 100.17537 | AL21: 100.13654 | AM21: 100.08451 | AN21: 100.01346 | AO21: 100.01253 | AP21: 100.02633 | AQ21: 100.84255 | AR21: 100.09404 | AS21: 100.03984 | AT21: 100.097 | AU21: 100.03634 | AV21: 100.04289 | AW21: 100.04831 | AX21: 100.07043 | AY21: 100.01824 | AZ21: 100.10741 | BA21: 100.02395 | BB21: 100.05938 | BC21: 100.04303
E22: 45938 | F22: 100.02275 | G22: 100.07432 | H22: 100.04334 | I22: 100.05494 | J22: 100.08362 | K22: 100.02492 | L22: 100.06088 | M22: 100.06184 | N22: 100.00087 | O22: 100.43739 | P22: 100.08982 | Q22: 99.915921 | R22: 100.00899 | S22: 100.0996 | T22: 100.05217 | U22: 100.19156 | V22: 100.04175 | W22: 100.23326 | X22: 100.09364 | Y22: 100.0531 | Z22: 100.13622 | AA22: 100.18386 | AB22: 100.04503 | AC22: 100.04338 | AD22: 99.96107 | AE22: 100.01671 | AF22: 100.07187 | AG22: 100.13295 | AH22: 100.28625 | AI22: 100.14953 | AJ22: 99.777303 | AK22: 100.18117 | AL22: 100.0585 | AM22: 100.11005 | AN22: 100.02889 | AO22: 100.00725 | AP22: 99.972737 | AQ22: 100.90367 | AR22: 100.21629 | AS22: 100.04375 | AT22: 100.12892 | AU22: 99.992782 | AV22: 99.989765 | AW22: 100.05205 | AX22: 100.09146 | AY22: 100.03014 | AZ22: 100.11396 | BA22: 100.01998 | BB22: 100.07426 | BC22: 100.04623
E23: 45939 | F23: 100.02112 | G23: 100.08318 | H23: 100.05288 | I23: 100.0507 | J23: 100.08299 | K23: 99.86056 | L23: 100.02524 | M23: 100.05405 | N23: 100.00536 | O23: 100.57777 | P23: 100.06339 | Q23: 99.749683 | R23: 99.963388 | S23: 100.07494 | T23: 100.03582 | U23: 100.14076 | V23: 99.953767 | W23: 100.18252 | X23: 100.09906 | Y23: 99.971989 | Z23: 100.12483 | AA23: 100.20722 | AB23: 100.04172 | AC23: 100.04091 | AD23: 99.887147 | AE23: 99.986807 | AF23: 100.08488 | AG23: 100.07278 | AH23: 100.29263 | AI23: 100.08891 | AJ23: 99.758081 | AK23: 100.07789 | AL23: 99.708659 | AM23: 100.16138 | AN23: 100.00052 | AO23: 99.951316 | AP23: 99.933547 | AQ23: 100.77295 | AR23: 100.36414 | AS23: 100.05168 | AT23: 100.06449 | AU23: 100.06002 | AV23: 100.06335 | AW23: 99.992399 | AX23: 100.05137 | AY23: 100.01736 | AZ23: 100.11043 | BA23: 100.02088 | BB23: 100.01981 | BC23: 100.02778
E24: 45940 | F24: 100.08561 | G24: 100.17789 | H24: 100.01036 | I24: 100.17628 | J24: 100.12143 | K24: 100.05331 | L24: 100.11562 | M24: 100.14284 | N24: 100.05327 | O24: 100.43545 | P24: 100.11808 | Q24: 99.627967 | R24: 100.10491 | S24: 100.15963 | T24: 100.10153 | U24: 100.31482 | V24: 100.15365 | W24: 100.16192 | X24: 100.259 | Y24: 100.14545 | Z24: 100.14295 | AA24: 100.28105 | AB24: 100.11317 | AC24: 100.19719 | AD24: 100.03634 | AE24: 100.19982 | AF24: 100.06261 | AG24: 100.2645 | AH24: 100.27472 | AI24: 100.22468 | AJ24: 99.925096 | AK24: 99.952429 | AL24: 99.098178 | AM24: 100.15841 | AN24: 100.01156 | AO24: 100.11875 | AP24: 100.0244 | AQ24: 100.29114 | AR24: 100.20306 | AS24: 100.1362 | AT24: 100.14895 | AU24: 100.0972 | AV24: 100.08767 | AW24: 100.08131 | AX24: 100.10495 | AY24: 100.05947 | AZ24: 100.14968 | BA24: 100.04834 | BB24: 100.16021 | BC24: 100.10882
E25: 45944 | F25: 100.09722 | G25: 100.23826 | H25: 100.03289 | I25: 100.266 | J25: 100.14685 | K25: 100.24153 | L25: 100.18426 | M25: 100.2735 | N25: 100.0404 | O25: 100.48175 | P25: 100.13862 | Q25: 99.780412 | R25: 100.27677 | S25: 100.2065 | T25: 100.24483 | U25: 100.53089 | V25: 100.18096 | W25: 100.21897 | X25: 100.49363 | Y25: 100.21714 | Z25: 100.16149 | AA25: 100.29602 | AB25: 100.17582 | AC25: 100.33617 | AD25: 100.14975 | AE25: 100.32372 | AF25: 100.07562 | AG25: 100.39422 | AH25: 100.31345 | AI25: 100.31347 | AJ25: 100.01941 | AK25: 99.8573 | AL25: 99.526579 | AM25: 100.18397 | AN25: 100.15825 | AO25: 100.26076 | AP25: 100.0045 | AQ25: 99.034789 | AR25: 100.31678 | AS25: 100.25293 | AT25: 100.27269 | AU25: 100.11422 | AV25: 100.10321 | AW25: 100.09684 | AX25: 100.10996 | AY25: 100.07648 | AZ25: 100.16923 | BA25: 100.05986 | BB25: 100.35223 | BC25: 100.14661
E26: 45945 | F26: 100.10443 | G26: 100.25145 | H26: 100.20268 | I26: 100.27972 | J26: 100.15925 | K26: 100.42948 | L26: 100.20081 | M26: 100.27419 | N26: 100.03186 | O26: 100.86815 | P26: 100.25302 | Q26: 99.912775 | R26: 100.30385 | S26: 100.23235 | T26: 100.23718 | U26: 100.53967 | V26: 100.21238 | W26: 100.19836 | X26: 100.49503 | Y26: 100.24646 | Z26: 100.2856 | AA26: 100.35725 | AB26: 100.15055 | AC26: 100.38521 | AD26: 100.25863 | AE26: 100.32233 | AF26: 100.09825 | AG26: 100.37967 | AH26: 100.41286 | AI26: 100.29139 | AJ26: 100.12273 | AK26: 100.06407 | AL26: 99.809948 | AM26: 100.19936 | AN26: 100.27859 | AO26: 100.29343 | AP26: 100.14817 | AQ26: 100.86444 | AR26: 100.40472 | AS26: 100.24078 | AT26: 100.26089 | AU26: 100.40052 | AV26: 100.36751 | AW26: 100.3581 | AX26: 100.34924 | AY26: 100.22737 | AZ26: 100.2986 | BA26: 100.19741 | BB26: 100.34125 | BC26: 100.13251
E27: 45946 | F27: 100.16451 | G27: 100.35467 | H27: 100.3334 | I27: 100.4274 | J27: 100.18902 | K27: 100.60029 | L27: 100.28246 | M27: 100.38387 | N27: 100.20122 | O27: 101.17759 | P27: 100.24799 | Q27: 100.0549 | R27: 100.44136 | S27: 100.34644 | T27: 100.35457 | U27: 100.68794 | V27: 100.47339 | W27: 100.26838 | X27: 100.70024 | Y27: 100.41121 | Z27: 100.27767 | AA27: 100.4437 | AB27: 100.23078 | AC27: 100.49841 | AD27: 100.40738 | AE27: 100.51878 | AF27: 100.28735 | AG27: 100.63266 | AH27: 100.56471 | AI27: 100.41003 | AJ27: 100.19431 | AK27: 100.20079 | AL27: 99.634814 | AM27: 100.24058 | AN27: 100.34213 | AO27: 100.41853 | AP27: 100.0898 | AQ27: 100.81759 | AR27: 100.57397 | AS27: 100.32533 | AT27: 100.34527 | AU27: 100.68428 | AV27: 100.62018 | AW27: 100.6009 | AX27: 100.55852 | AY27: 100.38402 | AZ27: 100.42619 | BA27: 100.31053 | BB27: 100.48567 | BC27: 100.22219
E28: 45947 | F28: 100.15409 | G28: 100.32499 | H28: 100.31704 | I28: 100.43221 | J28: 100.17103 | K28: 100.43273 | L28: 100.27732 | M28: 100.35102 | N28: 100.17971 | O28: 101.20612 | P28: 100.23012 | Q28: 99.92364 | R28: 100.40369 | S28: 100.30083 | T28: 100.31676 | U28: 100.62907 | V28: 100.2912 | W28: 100.37715 | X28: 100.55169 | Y28: 100.32192 | Z28: 100.38936 | AA28: 100.42086 | AB28: 100.21431 | AC28: 100.4747 | AD28: 100.32943 | AE28: 100.44876 | AF28: 100.30039 | AG28: 100.53993 | AH28: 100.4011 | AI28: 100.33246 | AJ28: 99.938873 | AK28: 100.11903 | AL28: 99.512676 | AM28: 100.3951 | AN28: 100.31391 | AO28: 100.30816 | AP28: 100.18057 | AQ28: 99.735497 | AR28: 100.63188 | AS28: 100.38975 | AT28: 100.31598 | AU28: 100.67622 | AV28: 100.64454 | AW28: 100.61999 | AX28: 100.5755 | AY28: 100.41126 | AZ28: 100.45207 | BA28: 100.3137 | BB28: 100.51791 | BC28: 100.1908
... E49: 45978 | F49: 100.29658 | G49: 100.49897 | H49: 100.17644 | I49: 100.54586 | J49: 100.48408 | K49: 100.31078 | L49: 100.38123 | M49: 100.57485 | N49: 100.41355 | O49: 102.3765 | P49: 100.57272 | Q49: 100.09566 | R49: 100.55518 | S49: 100.63809 | T49: 100.43162 | U49: 100.55545 | V49: 100.42697 | W49: 100.63987 | X49: 100.4557 | Y49: 100.18761 | Z49: 100.60315 | AA49: 100.81647 | AB49: 100.39603 | AC49: 100.31889 | AD49: 99.988466 | AE49: 100.26518 | AF49: 100.39846 | AG49: 100.5452 | AH49: 100.7683 | AI49: 100.61094 | AJ49: 98.655135 | AK49: 100.96671 | AL49: 100.61335 | AM49: 100.66752 | AN49: 100.32586 | AO49: 100.33524 | AP49: 100.15654 | AQ49: 94.480285 | AR49: 101.33927 | AS49: 100.75169 | AT49: 100.4923 | AU49: 100.59082 | AV49: 100.5636 | AW49: 100.55816 | AX49: 100.41164 | AY49: 100.50363 | AZ49: 100.61615 | BA49: 100.39039 | BB49: 100.17404 | BC49: 100.44005

Sheet Work with data
A1: =Daten!G16 -> AUSTRALIA AND NEW ZEALAND BANKING MTN | B1: =Daten!I16 -> BAIDU INC | C1: =Daten!L16 -> CITIGROUP INC | D1: =Daten!R16 -> GENERAL ELECTRIC CO MTN | E1: =Daten!AC16 -> LOCKHEED MARTIN CORPORATION | F1: =Daten!AE16 -> METLIFE INC | G1: =Daten!AJ16 -> ORACLE CORPORATION | H1: =Daten!AO16 -> ROYAL BANK OF CANADA MTN | I1: =Daten!AU16 -> TREASURY NOTE | J1: =Daten!AV16 -> TREASURY NOTE | K1: PORTFOLIO | N1: Eigenes Portfolio | O1: Benchmark | P1: Überrendite
A2: =Daten!G18/Daten!G17-1 -> 0.0001744 | B2: =Daten!I18/Daten!I17-1 -> 0.00067357356 | C2: =Daten!L18/Daten!L17-1 -> 0.00064227992 | D2: =Daten!R18/Daten!R17-1 -> 0.0008406143 | E2: =Daten!AC18/Daten!AC17-1 -> 0.0008326694 | F2: =Daten!AE18/Daten!AE17-1 -> 0.00095505566 | G2: =Daten!AJ18/Daten!AJ17-1 -> 0.00085005553 | H2: =Daten!AO18/Daten!AO17-1 -> 0.00087234766 | I2: =Daten!AU18/Daten!AU17-1 -> 0.00017 | J2: =Daten!AV18/Daten!AV17-1 -> 0.0001552 | K2: =AVERAGE(A2:J2) -> 0.0006166196 | M2: =Daten!E18 -> 45932 | N2: =K2 -> 0.0006166196 | O2: =AY76 -> 0.00078055603 | P2: =N2-O2 -> -0.00016393643
A3: =Daten!G19/Daten!G18-1 -> -0.00016891581 | B3: =Daten!I19/Daten!I18-1 -> -0.00031046521 | C3: =Daten!L19/Daten!L18-1 -> -0.00035527682 | D3: =Daten!R19/Daten!R18-1 -> -0.00079575386 | E3: =Daten!AC19/Daten!AC18-1 -> -0.00058131749 | F3: =Daten!AE19/Daten!AE18-1 -> -0.00090350204 | G3: =Daten!AJ19/Daten!AJ18-1 -> -0.0015478012 | H3: =Daten!AO19/Daten!AO18-1 -> -0.00068266995 | I3: =Daten!AU19/Daten!AU18-1 -> 0.00050857104 | J3: =Daten!AV19/Daten!AV18-1 -> 0.00049774165 | K3: =AVERAGE(A3:J3) -> -0.00043393896 | M3: =Daten!E19 -> 45933 | N3: {=PRODUCT(1+$K$2:K3)-1} -> 0.00018241306 | O3: {=PRODUCT(1+$AY$76:AY77)-1} -> 0.0009168526 | P3: =N3-O3 -> -0.00073443954
A4: =Daten!G20/Daten!G19-1 -> -4.0310284e-05 | B4: =Daten!I20/Daten!I19-1 -> -0.00035572434 | C4: =Daten!L20/Daten!L19-1 -> -0.00013869978 | D4: =Daten!R20/Daten!R19-1 -> -0.0012570567 | E4: =Daten!AC20/Daten!AC19-1 -> -0.0010125567 | F4: =Daten!AE20/Daten!AE19-1 -> -0.00082532669 | G4: =Daten!AJ20/Daten!AJ19-1 -> -0.0010086424 | H4: =Daten!AO20/Daten!AO19-1 -> -0.00089532084 | I4: =Daten!AU20/Daten!AU19-1 -> -0.002011763 | J4: =Daten!AV20/Daten!AV19-1 -> -0.0018203192 | K4: =AVERAGE(A4:J4) -> -0.00093657199 | M4: =Daten!E20 -> 45936 | N4: {=PRODUCT(1+$K$2:K4)-1} -> -0.00075432977 | O4: {=PRODUCT(1+$AY$76:AY78)-1} -> 0.00043858608 | P4: =N4-O4 -> -0.0011929159
A5: =Daten!G21/Daten!G20-1 -> 0.00081821266 | B5: =Daten!I21/Daten!I20-1 -> 0.0004950549 | C5: =Daten!L21/Daten!L20-1 -> 0.00046909978 | D5: =Daten!R21/Daten!R20-1 -> 0.0011487136 | E5: =Daten!AC21/Daten!AC20-1 -> 0.00096345431 | F5: =Daten!AE21/Daten!AE20-1 -> 0.00083600021 | G5: =Daten!AJ21/Daten!AJ20-1 -> -0.00060169747 | H5: =Daten!AO21/Daten!AO20-1 -> 0.00083225296 | I5: =Daten!AU21/Daten!AU20-1 -> 0.0017001004 | J5: =Daten!AV21/Daten!AV20-1 -> 0.0015992249 | K5: =AVERAGE(A5:J5) -> 0.00082604162 | M5: =Daten!E21 -> 45937 | N5: {=PRODUCT(1+$K$2:K5)-1} -> 7.1088744e-05 | O5: {=PRODUCT(1+$AY$76:AY79)-1} -> 0.00083432854 | P5: =N5-O5 -> -0.0007632398
A6: =Daten!G22/Daten!G21-1 -> -4.0098193e-05 | B6: =Daten!I22/Daten!I21-1 -> 4.7263976e-05 | C6: =Daten!L22/Daten!L21-1 -> -8.4309796e-06 | D6: =Daten!R22/Daten!R21-1 -> 0.00015548596 | E6: =Daten!AC22/Daten!AC21-1 -> 0.00023292932 | F6: =Daten!AE22/Daten!AE21-1 -> 0.00010646803 | G6: =Daten!AJ22/Daten!AJ21-1 -> 8.0886083e-05 | H6: =Daten!AO22/Daten!AO21-1 -> -5.2790742e-05 | I6: =Daten!AU22/Daten!AU21-1 -> -0.00043537833 | J6: =Daten!AV22/Daten!AV21-1 -> -0.00053099361 | K6: =AVERAGE(A6:J6) -> -4.4465848e-05 | M6: =Daten!E22 -> 45938 | N6: {=PRODUCT(1+$K$2:K6)-1} -> 2.6619735e-05 | O6: {=PRODUCT(1+$AY$76:AY80)-1} -> 0.00091762895 | P6: =N6-O6 -> -0.00089100922
A7: =Daten!G23/Daten!G22-1 -> 8.8571051e-05 | B7: =Daten!I23/Daten!I22-1 -> -4.2327444e-05 | C7: =Daten!L23/Daten!L22-1 -> -0.00035610983 | D7: =Daten!R23/Daten!R22-1 -> -0.0004559576 | E7: =Daten!AC23/Daten!AC22-1 -> -2.4689056e-05 | F7: =Daten!AE23/Daten!AE22-1 -> -0.00029903187 | G7: =Daten!AJ23/Daten!AJ22-1 -> -0.00019264694 | H7: =Daten!AO23/Daten!AO22-1 -> -0.00055925628 | I7: =Daten!AU23/Daten!AU22-1 -> 0.00067239479 | J7: =Daten!AV23/Daten!AV22-1 -> 0.0007358959 | K7: =AVERAGE(A7:J7) -> -4.3315729e-05 | M7: =Daten!E23 -> 45939 | N7: {=PRODUCT(1+$K$2:K7)-1} -> -1.6697147e-05 | O7: {=PRODUCT(1+$AY$76:AY81)-1} -> 0.00062697397 | P7: =N7-O7 -> -0.00064367112
A8: =Daten!G24/Daten!G23-1 -> 0.00094625059 | B8: =Daten!I24/Daten!I23-1 -> 0.0012551363 | C8: =Daten!L24/Daten!L23-1 -> 0.00090353771 | D8: =Daten!R24/Daten!R23-1 -> 0.0014156949 | E8: =Daten!AC24/Daten!AC23-1 -> 0.0015621796 | F8: =Daten!AE24/Daten!AE23-1 -> 0.0021304068 | G8: =Daten!AJ24/Daten!AJ23-1 -> 0.0016741993 | H8: =Daten!AO24/Daten!AO23-1 -> 0.0016751149 | I8: =Daten!AU24/Daten!AU23-1 -> 0.0003716532 | J8: =Daten!AV24/Daten!AV23-1 -> 0.00024311653 | K8: =AVERAGE(A8:J8) -> 0.001217729 | M8: =Daten!E24 -> 45940 | N8: {=PRODUCT(1+$K$2:K8)-1} -> 0.0012010115 | O8: {=PRODUCT(1+$AY$76:AY82)-1} -> 0.0010630049 | P8: =N8-O8 -> 0.00013800656
A9: =Daten!G25/Daten!G24-1 -> 0.00060261388 | B9: =Daten!I25/Daten!I24-1 -> 0.00089562708 | C9: =Daten!L25/Daten!L24-1 -> 0.00068562485 | D9: =Daten!R25/Daten!R24-1 -> 0.0017168881 | E9: =Daten!AC25/Daten!AC24-1 -> 0.001387111 | F9: =Daten!AE25/Daten!AE24-1 -> 0.0012365335 | G9: =Daten!AJ25/Daten!AJ24-1 -> 0.00094383714 | H9: =Daten!AO25/Daten!AO24-1 -> 0.0014184539 | I9: =Daten!AU25/Daten!AU24-1 -> 0.00017 | J9: =Daten!AV25/Daten!AV24-1 -> 0.0001552 | K9: =AVERAGE(A9:J9) -> 0.00092118893 | M9: =Daten!E25 -> 45944 | N9: {=PRODUCT(1+$K$2:K9)-1} -> 0.0021233068 | O9: {=PRODUCT(1+$AY$76:AY83)-1} -> 0.0016058252 | P9: =N9-O9 -> 0.00051748161
A10: =Daten!G26/Daten!G25-1 -> 0.00013159761 | B10: =Daten!I26/Daten!I25-1 -> 0.0001368 | C10: =Daten!L26/Daten!L25-1 -> 0.0001652 | D10: =Daten!R26/Daten!R25-1 -> 0.00027 | E10: =Daten!AC26/Daten!AC25-1 -> 0.00048876286 | F10: =Daten!AE26/Daten!AE25-1 -> -1.3834521e-05 | G10: =Daten!AJ26/Daten!AJ25-1 -> 0.0010330213 | H10: =Daten!AO26/Daten!AO25-1 -> 0.00032585206 | I10: =Daten!AU26/Daten!AU25-1 -> 0.0028597475 | J10: =Daten!AV26/Daten!AV25-1 -> 0.002640258 | K10: =AVERAGE(A10:J10) -> 0.00080374049 | M10: =Daten!E26 -> 45945 | N10: {=PRODUCT(1+$K$2:K10)-1} -> 0.0029287539 | O10: {=PRODUCT(1+$AY$76:AY84)-1} -> 0.0027900884 | P10: =N10-O10 -> 0.00013866542
A11: =Daten!G27/Daten!G26-1 -> 0.0010296474 | B11: =Daten!I27/Daten!I26-1 -> 0.0014726807 | C11: =Daten!L27/Daten!L26-1 -> 0.00081485529 | D11: =Daten!R27/Daten!R26-1 -> 0.00137097 | E11: =Daten!AC27/Daten!AC26-1 -> 0.0011276332 | F11: =Daten!AE27/Daten!AE26-1 -> 0.001958179 | G11: =Daten!AJ27/Daten!AJ26-1 -> 0.00071492473 | H11: =Daten!AO27/Daten!AO26-1 -> 0.0012473513 | I11: =Daten!AU27/Daten!AU26-1 -> 0.0028262436 | J11: =Daten!AV27/Daten!AV26-1 -> 0.0025174679 | K11: =AVERAGE(A11:J11) -> 0.0015079953 | M11: =Daten!E27 -> 45946 | N11: {=PRODUCT(1+$K$2:K11)-1} -> 0.0044411657 | O11: {=PRODUCT(1+$AY$76:AY85)-1} -> 0.0040249022 | P11: =N11-O11 -> 0.00041626351
A12: =Daten!G28/Daten!G27-1 -> -0.00029577763 | B12: =Daten!I28/Daten!I27-1 -> 4.7869011e-05 | C12: =Daten!L28/Daten!L27-1 -> -5.1243803e-05 | D12: =Daten!R28/Daten!R27-1 -> -0.00037505767 | E12: =Daten!AC28/Daten!AC27-1 -> -0.00023594598 | F12: =Daten!AE28/Daten!AE27-1 -> -0.00069658711 | G12: =Daten!AJ28/Daten!AJ27-1 -> -0.0025494365 | H12: =Daten!AO28/Daten!AO27-1 -> -0.0010990919 | I12: =Daten!AU28/Daten!AU27-1 -> -8.0056115e-05 | J12: =Daten!AV28/Daten!AV27-1 -> 0.00024212322 | K12: =AVERAGE(A12:J12) -> -0.00050932044 | M12: =Daten!E28 -> 45947 | N12: {=PRODUCT(1+$K$2:K12)-1} -> 0.0039295833 | O12: {=PRODUCT(1+$AY$76:AY86)-1} -> 0.0035052646 | P12: =N12-O12 -> 0.00042431872
A13: =Daten!G29/Daten!G28-1 -> 0.00013163133 | B13: =Daten!I29/Daten!I28-1 -> -0.00044169573 | C13: =Daten!L29/Daten!L28-1 -> -8.0327434e-06 | D13: =Daten!R29/Daten!R28-1 -> 0.00061162046 | E13: =Daten!AC29/Daten!AC28-1 -> 0.00091385979 | F13: =Daten!AE29/Daten!AE28-1 -> 0.0010722663 | G13: =Daten!AJ29/Daten!AJ28-1 -> 0.00085395955 | H13: =Daten!AO29/Daten!AO28-1 -> 0.0012898236 | I13: =Daten!AU29/Daten!AU28-1 -> -0.00074244165 | J13: =Daten!AV29/Daten!AV28-1 -> -0.00065821204 | K13: =AVERAGE(A13:J13) -> 0.00030227789 | M13: =Daten!E29 -> 45950 | N13: {=PRODUCT(1+$K$2:K13)-1} -> 0.004233049 | O13: {=PRODUCT(1+$AY$76:AY87)-1} -> 0.0038649797 | P13: =N13-O13 -> 0.00036806934
A14: =Daten!G30/Daten!G29-1 -> 0.0001744 | B14: =Daten!I30/Daten!I29-1 -> 0.0007597635 | C14: =Daten!L30/Daten!L29-1 -> 0.00012188102 | D14: =Daten!R30/Daten!R29-1 -> 0.0010281959 | E14: =Daten!AC30/Daten!AC29-1 -> 0.00074272691 | F14: =Daten!AE30/Daten!AE29-1 -> 0.00062945546 | G14: =Daten!AJ30/Daten!AJ29-1 -> -0.001785823 | H14: =Daten!AO30/Daten!AO29-1 -> 0.0007020746 | I14: =Daten!AU30/Daten!AU29-1 -> 0.00099764418 | J14: =Daten!AV30/Daten!AV29-1 -> 0.00083387364 | K14: =AVERAGE(A14:J14) -> 0.00042041922 | M14: =Daten!E30 -> 45951 | N14: {=PRODUCT(1+$K$2:K14)-1} -> 0.0046552479 | O14: {=PRODUCT(1+$AY$76:AY88)-1} -> 0.004574828 | P14: =N14-O14 -> 8.0419912e-05
... A33: =Daten!G49/Daten!G48-1 -> 0.00026032234 | B33: =Daten!I49/Daten!I48-1 -> -0.000443241 | C33: =Daten!L49/Daten!L48-1 -> 0.00025229405 | D33: =Daten!R49/Daten!R48-1 -> 7.8351578e-05 | E33: =Daten!AC49/Daten!AC48-1 -> -2.5755622e-05 | F33: =Daten!AE49/Daten!AE48-1 -> -0.00022122091 | G33: =Daten!AJ49/Daten!AJ48-1 -> 0.000172 | H33: =Daten!AO49/Daten!AO48-1 -> 0.00041179931 | I33: =Daten!AU49/Daten!AU48-1 -> 0.00070567143 | J33: =Daten!AV49/Daten!AV48-1 -> 0.00099822622 | K33: =AVERAGE(A33:J33) -> 0.00021884474 | M33: =Daten!E49 -> 45978 | N33: {=PRODUCT(1+$K$2:K33)-1} -> 0.0027026617 | O33: {=PRODUCT(1+$AY$76:AY107)-1} -> 0.0036800932 | P33: =N33-O33 -> -0.00097743148
A34: {=PRODUCT(1+A2:A33)-1} -> 0.004989743 | B34: {=PRODUCT(1+B2:B33)-1} -> 0.0054585559 | C34: {=PRODUCT(1+C2:C33)-1} -> 0.0038123479 | D34: {=PRODUCT(1+D2:D33)-1} -> 0.0055517901 | E34: {=PRODUCT(1+E2:E33)-1} -> 0.0031889049 | F34: {=PRODUCT(1+F2:F33)-1} -> 0.0026517724 | G34: {=PRODUCT(1+G2:G33)-1} -> -0.013448649 | H34: {=PRODUCT(1+H2:H33)-1} -> 0.0033523638 | ... K34: {=PRODUCT(1+K2:K33)-1} -> 0.0027026617
B36: Returns | C36: Maturity | D36: Coupon | E36: YTM | F36: Spread | G36: Mod Dur | H36: Rating | I36: Rest time | J36: Num Rating | K36: Ret Ranking
A37: {=TRANSPOSE(A1:K1)} -> AUSTRALIA AND NEW ZEALAND BANKING MTN | B37: {=TRANSPOSE(A34:K34)} -> 0.004989743 | C37: 46922 | D37: ='FIM IA 2'!J25/100 -> 0.0436 | E37: ='FIM IA 2'!K25 -> 0.0385 | F37: ='FIM IA 2'!M25 -> 0.0041 | G37: ='FIM IA 2'!N25 -> 2.58 | H37: ='FIM IA 2'!L25 -> AA- | I37: =(C37-Daten!$E$49)/365 -> 2.5863014 | J37: =VLOOKUP(H37,$A$51:$B$72,2,FALSE) -> 4 | K37: =_xlfn.RANK.EQ(B37,$B$37:$B$46) -> 5
A38: BAIDU INC | B38: 0.0054585559 | C38: 47580 | D38: ='FIM IA 2'!J27/100 -> 0.0342 | E38: ='FIM IA 2'!K27 -> 0.0411 | F38: ='FIM IA 2'!M27 -> 0.0063 | G38: ='FIM IA 2'!N27 -> 4.13 | H38: ='FIM IA 2'!L27 -> A | I38: =(C38-Daten!$E$49)/365 -> 4.3890411 | J38: =VLOOKUP(H38,$A$51:$B$72,2,FALSE) -> 6 | K38: =_xlfn.RANK.EQ(B38,$B$37:$B$46) -> 4
A39: CITIGROUP INC | B39: 0.0038123479 | C39: 46959 | D39: ='FIM IA 2'!J30/100 -> 0.0413 | E39: ='FIM IA 2'!K30 -> 0.041 | F39: ='FIM IA 2'!M30 -> 0.0067 | G39: ='FIM IA 2'!N30 -> 2.69 | H39: ='FIM IA 2'!L30 -> BBB+ | I39: =(C39-Daten!$E$49)/365 -> 2.6876712 | J39: =VLOOKUP(H39,$A$51:$B$72,2,FALSE) -> 8 | K39: =_xlfn.RANK.EQ(B39,$B$37:$B$46) -> 6
A40: GENERAL ELECTRIC CO MTN | B40: 0.0055517901 | C40: 48288 | D40: ='FIM IA 2'!J36/100 -> 0.0675 | E40: ='FIM IA 2'!K36 -> 0.0426 | F40: ='FIM IA 2'!M36 -> 0.007 | G40: ='FIM IA 2'!N36 -> 5.21 | H40: ='FIM IA 2'!L36 -> A- | I40: =(C40-Daten!$E$49)/365 -> 6.3287671 | J40: =VLOOKUP(H40,$A$51:$B$72,2,FALSE) -> 7 | K40: =_xlfn.RANK.EQ(B40,$B$37:$B$46) -> 3
A41: LOCKHEED MARTIN CORPORATION | B41: 0.0031889049 | C41: 48990 | D41: ='FIM IA 2'!J47/100 -> 0.0475 | E41: ='FIM IA 2'!K47 -> 0.046 | F41: ='FIM IA 2'!M47 -> 0.0086 | G41: ='FIM IA 2'!N47 -> 6.89 | H41: ='FIM IA 2'!L47 -> A- | I41: =(C41-Daten!$E$49)/365 -> 8.2520548 | J41: =VLOOKUP(H41,$A$51:$B$72,2,FALSE) -> 7 | K41: =_xlfn.RANK.EQ(B41,$B$37:$B$46) -> 8
A42: METLIFE INC | B42: 0.0026517724 | C42: 49475 | D42: ='FIM IA 2'!J49/100 -> 0.057 | E42: ='FIM IA 2'!K49 -> 0.0476 | F42: ='FIM IA 2'!M49 -> 0.0096 | G42: ='FIM IA 2'!N49 -> 7.45 | H42: ='FIM IA 2'!L49 -> A | I42: =(C42-Daten!$E$49)/365 -> 9.5808219 | J42: =VLOOKUP(H42,$A$51:$B$72,2,FALSE) -> 6 | K42: =_xlfn.RANK.EQ(B42,$B$37:$B$46) -> 9
A43: ORACLE CORPORATION | B43: -0.013448649 | C43: 49133 | D43: ='FIM IA 2'!J54/100 -> 0.043 | E43: ='FIM IA 2'!K54 -> 0.0486 | F43: ='FIM IA 2'!M54 -> 0.0109 | G43: ='FIM IA 2'!N54 -> 7.19 | H43: ='FIM IA 2'!L54 -> BBB | I43: =(C43-Daten!$E$49)/365 -> 8.6438356 | J43: =VLOOKUP(H43,$A$51:$B$72,2,FALSE) -> 9 | K43: =_xlfn.RANK.EQ(B43,$B$37:$B$46) -> 10
A44: ROYAL BANK OF CANADA MTN | B44: 0.0033523638 | C44: 48701 | D44: ='FIM IA 2'!J59/100 -> 0.05 | E44: ='FIM IA 2'!K59 -> 0.0448 | F44: ='FIM IA 2'!M59 -> 0.0081 | G44: ='FIM IA 2'!N59 -> 6.24 | H44: ='FIM IA 2'!L59 -> AA- | I44: =(C44-Daten!$E$49)/365 -> 7.460274 | J44: =VLOOKUP(H44,$A$51:$B$72,2,FALSE) -> 4 | K44: =_xlfn.RANK.EQ(B44,$B$37:$B$46) -> 7
A45: TREASURY NOTE | B45: 0.0059082415 | C45: 49444 | D45: ='FIM IA 2'!J65/100 -> 0.0425 | E45: ='FIM IA 2'!K65 -> 0.0407 | F45: ='FIM IA 2'!M65 -> 0.0023 | G45: ='FIM IA 2'!N65 -> 7.8 | H45: ='FIM IA 2'!L65 -> AA+ | I45: =(C45-Daten!$E$49)/365 -> 9.4958904 | J45: =VLOOKUP(H45,$A$51:$B$72,2,FALSE) -> 2 | K45: =_xlfn.RANK.EQ(B45,$B$37:$B$46) -> 1
A46: TREASURY NOTE | B46: 0.0056360443 | C46: 49171 | D46: ='FIM IA 2'!J66/100 -> 0.0388 | E46: ='FIM IA 2'!K66 -> 0.04 | F46: ='FIM IA 2'!M66 -> 0.002 | G46: ='FIM IA 2'!N66 -> 7.47 | H46: ='FIM IA 2'!L66 -> AA+ | I46: =(C46-Daten!$E$49)/365 -> 8.7479452 | J46: =VLOOKUP(H46,$A$51:$B$72,2,FALSE) -> 2 | K46: =_xlfn.RANK.EQ(B46,$B$37:$B$46) -> 2
A47: PORTFOLIO | B47: 0.0027026617 | E47: =AVERAGE(E37:E46) -> 0.04309 | F47: =AVERAGE(F37:F46) -> 0.00656 | G47: =AVERAGE(G37:G46) -> 5.765 | J47: =ROUND(AVERAGE(J37:J46),0) -> 6
A50: Rating
A51: AAA | B51: 1 | C51: =COUNTIF('FIM IA 2'!$L$24:$L$73,'Work with data'!A51) -> 0
A52: AA+ | B52: 2 | C52: =COUNTIF('FIM IA 2'!$L$24:$L$73,'Work with data'!A52) -> 8
A53: AA | B53: 3 | C53: =COUNTIF('FIM IA 2'!$L$24:$L$73,'Work with data'!A53) -> 1
A54: AA- | B54: 4 | C54: =COUNTIF('FIM IA 2'!$L$24:$L$73,'Work with data'!A54) -> 5
A55: A+ | B55: 5 | C55: =COUNTIF('FIM IA 2'!$L$24:$L$73,'Work with data'!A55) -> 2
A56: A | B56: 6 | C56: =COUNTIF('FIM IA 2'!$L$24:$L$73,'Work with data'!A56) -> 2
A57: A- | B57: 7 | C57: =COUNTIF('FIM IA 2'!$L$24:$L$73,'Work with data'!A57) -> 7
A58: BBB+ | B58: 8 | C58: =COUNTIF('FIM IA 2'!$L$24:$L$73,'Work with data'!A58) -> 5
A59: BBB | B59: 9 | C59: =COUNTIF('FIM IA 2'!$L$24:$L$73,'Work with data'!A59) -> 10
A60: BBB- | B60: 10 | C60: =COUNTIF('FIM IA 2'!$L$24:$L$73,'Work with data'!A60) -> 4
A61: BB+ | B61: 11 | C61: =COUNTIF('FIM IA 2'!$L$24:$L$73,'Work with data'!A61) -> 1
...
