Workbook

Sheet Renditen
B1: Anlage-kategorie 1 | C1: Anlage-kategorie 2 | D1: Anlage-kategorie 3 | E1: Anlage-kategorie 4 | F1: Anlage-kategorie 5 | G1: Anlage-kategorie 6 | H1: Anlage-kategorie 7 | I1: Anlage-kategorie 8 | J1: Anlage-kategorie 9 | M1: Anlage-kategorie 1 | N1: Anlage-kategorie 2 | O1: Anlage-kategorie 3 | P1: Anlage-kategorie 4 | Q1: Anlage-kategorie 5 | R1: Anlage-kategorie 6 | S1: Anlage-kategorie 7 | T1: Anlage-kategorie 8 | U1: Anlage-kategorie 9 | W1: Risikoloser Zinssatz p.m. (SARON 1M)
A3: Monatliche Portfoliorenditen | L3: Monatliche Benchmarkrenditen
A4: 43496 | B4: 0.0002 | C4: 0.006 | D4: 0.044948758 | E4: 0.0694 | F4: 0.071 | G4: 0.0944 | H4: 0.0062631383 | I4: 0.0034 | J4: 0.020616561 | L4: 43496 | M4: -0.0007548188 | N4: 0.0032872105 | O4: 0.0060515221 | P4: 0.069611986 | Q4: 0.071190243 | R4: 0.094508223 | S4: 0.11255421 | T4: 0.0032002074 | U4: 0.10215547 | W4: -0.0006105 | Z4: = Musterdaten
A5: 43524 | B5: -0.0015 | C5: -0.0001 | D5: 0.0065972709 | E5: 0.0428 | F5: 0.031 | G5: 0.0064 | H5: 0.0019646078 | I5: 0.0034 | J5: 0.027686931 | L5: 43524 | M5: -0.0006645346 | N5: 0.0009143554 | O5: -0.0034903096 | P5: 0.042809113 | Q5: 0.031016597 | R5: 0.0063896427 | S5: 0.031202208 | T5: 0.0029008639 | U5: 0.0017164257 | W5: -0.0006115
A6: 43555 | B6: -0.0009 | C6: 0.0136 | D6: 0.006478307 | E6: 0.025 | F6: 0.0139 | G6: 0.0082 | H6: -0.011191924 | I6: 0.0034 | J6: -0.0011629374 | L6: 43555 | M6: -0.0007238546 | N6: 0.0069275274 | O6: 0.016110281 | P6: 0.025238817 | Q6: 0.013615985 | R6: 0.0080883027 | S6: 0.0049520346 | T6: 0.0040374305 | U6: 0.036762033 | W6: -0.0006113333
A7: 43585 | B7: 0.0018 | C7: -0.0036 | D7: 0.0011534783 | E7: 0.0439 | F7: 0.0363 | G7: 0.0446 | H7: 0.021944438 | I7: 0.0034 | J7: -0.0041285366 | L7: 43585 | M7: -0.0006671912 | N7: -0.0010584411 | O7: -0.0046166127 | P7: 0.043942857 | Q7: 0.036417713 | R7: 0.044736907 | S7: 0.090216525 | T7: 0.0030764759 | U7: -0.012771072 | W7: -0.000613
A8: 43616 | B8: -0.0014 | C8: 0.0148 | D8: -0.002514539 | E8: -0.0162 | F8: -0.0601 | G8: -0.084 | H8: -0.012895953 | I8: 0.0034 | J8: -0.024511031 | L8: 43616 | M8: -0.0006780413 | N8: 0.0070385227 | O8: 0.014759133 | P8: -0.016243494 | Q8: -0.059758692 | R8: -0.084531189 | S8: -0.052715754 | T8: 0.0037389782 | U8: -0.00390625 | W8: -0.0006135
A9: 43646 | B9: -0.0052 | C9: 0.0042 | D9: 0.030189758 | E9: 0.0378 | F9: 0.0562 | G9: 0.0289 | H9: -0.007392797 | I9: 0.0034 | J9: 0.0035953017 | L9: 43646 | M9: -0.0006533396 | N9: 0.0018788516 | O9: 0.011099919 | P9: 0.037493049 | Q9: 0.056043465 | R9: 0.029827848 | S9: 0.045656276 | T9: 0.0034879203 | U9: 0.0079959256 | W9: -0.0006123333
A10: 43677 | B10: -0.0005 | C10: 0.0151 | D10: 0.010704692 | E10: 0.0074 | F10: 0.0098 | G10: 0.0026 | H10: 0.015047329 | I10: 0.0034 | J10: 0.0064081417 | L10: 43677 | M10: -0.0006772085 | N10: 0.0078763784 | O10: 0.0049914369 | P10: 0.0072695364 | Q10: 0.0098629024 | R10: 0.0029681938 | S10: 0.02698717 | T10: 0.0038931278 | U10: 0.0087914309 | W10: -0.0006144167
A11: 43708 | B11: -0.0006 | C11: 0.0236 | D11: 0.004254427 | E11: -0.0003 | F11: -0.0225 | G11: -0.0502 | H11: 0.0007244068 | I11: 0.0034 | J11: 0.011801235 | L11: 43708 | M11: -0.0007098132 | N11: 0.0081125335 | O11: 0.02603982 | P11: -0.0002925952 | Q11: -0.02236812 | R11: -0.049284747 | S11: -0.001047824 | T11: 0.0037444203 | U11: 0.018230993 | W11: -0.0006189167
A12: 43738 | B12: -0.0009 | C12: -0.0191 | D12: -0.0079212613 | E12: 0.0142 | F12: 0.0214 | G12: 0.0271 | H12: 0.042028618 | I12: 0.0034 | J12: 0.016775617 | L12: 43738 | M12: -0.0007450943 | N12: -0.011074197 | O12: -0.0088296001 | P12: 0.014278347 | Q12: 0.021553657 | R12: 0.027019878 | S12: 0.029634237 | T12: 0.0059245594 | U12: 0.025135268 | W12: -0.0006134167
A13: 43769 | B13: -0.0007 | C13: -0.0163 | D13: 3.0833443e-05 | E13: 0.0085 | F13: 0.0168 | G13: 0.0322 | H13: -0.010759448 | I13: 0.0034 | J13: 0.0044726026 | L13: 43769 | M13: -0.0008013343 | N13: -0.0078387458 | O13: -0.0067994627 | P13: 0.0084949641 | Q13: 0.016858099 | R13: 0.031297891 | S13: 0.018882556 | T13: 0.0035520002 | U13: 0.016985749 | W13: -0.0006144167
A14: 43799 | B14: -0.0004 | C14: 0.008 | D14: -0.0058873588 | E14: 0.0275 | F14: 0.0302 | G14: 0.0112 | H14: 0.012698972 | I14: 0.0034 | J14: -0.0026504667 | L14: 43799 | M14: -0.0007723709 | N14: 0.0038374718 | O14: -0.0063015328 | P14: 0.027483069 | Q14: 0.030263891 | R14: 0.011374488 | S14: 0.037233956 | T14: 0.0037917295 | U14: -0.0098608162 | W14: -0.0005688333
A15: 43830 | B15: -0.0036 | C15: -0.0115 | D15: 0.017773747 | E15: 0.0127 | F15: 0.0201 | G15: 0.0416 | H15: -0.034845931 | I15: 0.0161 | J15: -0.0022522752 | L15: 43830 | M15: -0.0007389817 | N15: -0.0057716813 | O15: -0.0087916347 | P15: 0.012731824 | Q15: 0.020315426 | R15: 0.041271055 | S15: 0.0080610527 | T15: 0.0093009384 | U15: -0.0034308587 | W15: -0.0005850833
A16: 43861 | B16: -0.0012 | C16: 0.0221 | D16: 0.012416093 | E16: 0.0026 | F16: -0.0049 | G16: -0.0537 | H16: -0.0042856043 | I16: 0.0033 | J16: 0.0097546411 | L16: 43861 | M16: -0.0007116215 | N16: 0.0098763571 | O16: 0.020352113 | P16: 0.0026087634 | Q16: -0.004481745 | R16: -0.050454774 | S16: 0.016060696 | T16: 0.0032476914 | U16: 0.011379937 | W16: -0.0005855
... A69: 45473 | B69: -0.0032351343 | C69: 0.0139 | D69: 0.043428889 | E69: 0.0235 | F69: 0.038 | G69: 0.0044 | H69: -0.040692859 | I69: 0.0071 | J69: 0.0003 | L69: 45473 | M69: 0.0013643104 | N69: 0.0074846723 | O69: 0.027161273 | P69: 0.023522883 | Q69: 0.037668126 | R69: 0.0057535791 | S69: 0.054803164 | T69: -0.0002020001 | U69: 0.081410974 | W69: 0.0014176667

Sheet Vermögen
B1: Anlage-kategorie 1 | C1: Anlage-kategorie 2 | D1: Anlage-kategorie 3 | E1: Anlage-kategorie 4 | F1: Anlage-kategorie 5 | G1: Anlage-kategorie 6 | H1: Anlage-kategorie 7 | I1: Anlage-kategorie 8 | J1: Anlage-kategorie 9
A3: Vermögensstand in CHF
A4: 43465 | B4: 15000000 | C4: 192050000 | D4: 97275000 | E4: 136940000 | F4: 154260000 | G4: 112305000 | H4: 76926300 | I4: 152568000 | J4: 36489000
A5: 43496 | B5: 15003000 | C5: 193202300 | D5: 1.0164739e+08 | E5: 146443636 | F5: 165212460 | G5: 122906592 | H5: 77408100 | I5: 1.5308673e+08 | J5: 37241278 | M5: = Musterdaten
A6: 43524 | B6: 14980496 | C6: 1.9318298e+08 | D6: 1.0231799e+08 | E6: 1.5271142e+08 | F6: 1.7033405e+08 | G6: 1.2369319e+08 | H6: 77560177 | I6: 1.5360723e+08 | J6: 38272374
A7: 43555 | B7: 14967013 | C7: 1.9581027e+08 | D7: 1.0298083e+08 | E7: 1.5652921e+08 | F7: 1.7270169e+08 | G7: 1.2470748e+08 | H7: 76692129 | I7: 1.5412949e+08 | J7: 38227866
A8: 43585 | B8: 14993954 | C8: 1.9510535e+08 | D8: 1.0309962e+08 | E8: 1.6340084e+08 | F8: 1.7897076e+08 | G8: 1.3026943e+08 | H8: 78375095 | I8: 1.5465353e+08 | J8: 38070041
A9: 43616 | B9: 14972962 | C9: 1.9799291e+08 | D9: 1.0284037e+08 | E9: 1.6075375e+08 | F9: 1.6821462e+08 | G9: 1.193268e+08 | H9: 77364373 | I9: 1.5517935e+08 | J9: 37136905
A10: 43646 | B10: 14895103 | C10: 1.9882448e+08 | D10: 1.059451e+08 | E10: 1.6683024e+08 | F10: 1.7766828e+08 | G10: 1.2277534e+08 | H10: 76792434 | I10: 1.5570696e+08 | J10: 37270423
A11: 43677 | B11: 14887655 | C11: 2.0182673e+08 | D11: 1.0707921e+08 | E11: 1.6806478e+08 | F11: 1.7940943e+08 | G11: 1.2309456e+08 | H11: 77947955 | I11: 1.5623637e+08 | J11: 37509257
A12: 43708 | B12: 14878723 | C12: 2.0658984e+08 | D12: 1.0753477e+08 | E12: 1.6801436e+08 | F12: 1.7537272e+08 | G12: 1.1691521e+08 | H12: 78004421 | I12: 1.5676757e+08 | J12: 37951913
A13: 43738 | B13: 14865332 | C13: 2.0264398e+08 | D13: 1.0668296e+08 | E13: 1.7040017e+08 | F13: 1.7912569e+08 | G13: 1.2008362e+08 | H13: 81282839 | I13: 1.5730058e+08 | J13: 38588580
A14: 43769 | B14: 14854926 | C14: 1.9934088e+08 | D14: 1.0668625e+08 | E14: 1.7184857e+08 | F14: 1.82135e+08 | G14: 1.2395031e+08 | H14: 80408281 | I14: 1.578354e+08 | J14: 38761171
A15: 43799 | B15: 14848984 | C15: 2.0093561e+08 | D15: 1.0605815e+08 | E15: 1.765744e+08 | F15: 1.8763548e+08 | G15: 1.2533855e+08 | H15: 81429383 | I15: 1.5837204e+08 | J15: 38658436
A16: 43830 | B16: 14795528 | C16: 1.9862485e+08 | D16: 1.079432e+08 | E16: 1.788169e+08 | F16: 1.9140695e+08 | G16: 1.3055263e+08 | H16: 78591901 | I16: 1.6092183e+08 | J16: 38571367
A17: 43861 | B17: 14777773 | C17: 2.0301446e+08 | D17: 1.0928343e+08 | E17: 1.7928182e+08 | F17: 1.9046906e+08 | G17: 1.2354196e+08 | H17: 78255087 | I17: 1.6145287e+08 | J17: 38947616
... A70: 45473 | B70: 13682781 | C70: 1.8464598e+08 | D70: 95744169 | E70: 2.0290069e+08 | F70: 2.5703629e+08 | G70: 1.1353757e+08 | H70: 1.1671205e+08 | I70: 1.6927619e+08 | J70: 40163036

Sheet Strategie
A1: Anlagekategorien (konkrete Bezeichnungen werden am Seminartag bekanntgegeben) | B1: Strategie-quote | C1: Taktische Bandbreiten | E1: Benchmarks (konkrete Bezeichnungen werden am Seminartag bekanntgegeben) | G1: Anlagekategorien gemäss KVAV (in % des Vermögens der jeweiligen Anlagekategorie)
G2: Anlageinstrument | K2: Währung
C3: Min | D3: Max | G3: Anteil Aktien | H3: Anteil Immobilien Schweiz | I3: Anteil Immobilien Welt | J3: Anteil nicht geeignete Anlagen | K3: Anteil CHF | L3: Anteil Fremd-währungen
A4: Anlagekategorie 1 | B4: 0.02 | C4: 0.01 | D4: 0.03 | E4: Benchmark 1 | G4: 0 | H4: 0 | I4: 0 | J4: 0 | K4: 1 | L4: 0 | O4: = Musterdaten
A5: Anlagekategorie 2 | B5: 0.2 | C5: 0.17 | D5: 0.23 | E5: Benchmark 2 | G5: 0 | H5: 0 | I5: 0 | J5: 0 | K5: 1 | L5: 0
A6: Anlagekategorie 3 | B6: 0.1 | C6: 0.07 | D6: 0.13 | E6: Benchmark 3 | G6: 0 | H6: 0 | I6: 0 | J6: 0 | K6: 1 | L6: 0
A7: Anlagekategorie 4 | B7: 0.12 | C7: 0.08 | D7: 0.16 | E7: Benchmark 4 | G7: 1 | H7: 0 | I7: 0 | J7: 0 | K7: 1 | L7: 0
A8: Anlagekategorie 5 | B8: 0.16 | C8: 0.12 | D8: 0.2 | E8: Benchmark 5 | G8: 1 | H8: 0 | I8: 0 | J8: 0 | K8: 1 | L8: 0
A9: Anlagekategorie 6 | B9: 0.12 | C9: 0.08 | D9: 0.16 | E9: Benchmark 6 | G9: 1 | H9: 0 | I9: 0 | J9: 0 | K9: 0 | L9: 1
A10: Anlagekategorie 7 | B10: 0.08 | C10: 0.06 | D10: 0.1 | E10: Benchmark 7 | G10: 0 | H10: 0 | I10: 0 | J10: 1 | K10: 0 | L10: 1
A11: Anlagekategorie 8 | B11: 0.16 | C11: 0.13 | D11: 0.19 | E11: Benchmark 8 | G11: 0 | H11: 1 | I11: 0 | J11: 0 | K11: 1 | L11: 0
A12: Anlagekategorie 9 | B12: 0.04 | C12: 0.02 | D12: 0.06 | E12: Benchmark 9 | G12: 0 | H12: 0 | I12: 1 | J12: 0 | K12: 1 | L12: 0
A13: Total | B13: =SUM(B4:B12) -> 1 | E13: Strategische Benchmark

Sheet Lösungsraster
A1: Lösungsraster
A3: a) / b) | B3: Vermögensstruktur per 30.06.2024 mit Strategiequoten, Bandbreiten, Einhaltung KVAV Maximallimiten sowie Deckung des Sollbetrags
K4: Hinweis: Sollbetrag als gebundenes Vermögen nehmen.
B5: 45473 | C5: Vermögen in CHF | D5: Vermögen in % | E5: Strategiequoten in % | F5: Bandbreiten in % | H5: KVAV Maximallimiten in % | I5: Maximal zurechenbarer Betrag in CHF | J5: davon nicht anrechenbar an gebundenes Vermögen in CHF | K5: davon anrechenbar an gebundenes Vermögen in CHF | L5: gebundenes Vermögen nach Abzug nicht anrechenbare Fremdwährungen in CHF | M5: Sollbetrag in CHF
F6: Min. | G6: Max.
B7: Anlagekategorie 1 | C7: =Vermögen!B70 -> 13682781 | D7: =C7/$C$16 -> 0.011462508 | E7: =Strategie!B4 -> 0.02 | F7: =Strategie!C4 -> 0.01 | G7: =Strategie!D4 -> 0.03 | H7: 1 | I7: =H7*M16 -> 990000000 | J7: =IF(C7>I7,C7-I7,0) -> 0 | K7: =IF(J7=0,C7,I7) -> 13682781
B8: Anlagekategorie 2 | C8: =Vermögen!C70 -> 1.8464598e+08 | D8: =C8/$C$16 -> 0.1546839 | E8: =Strategie!B5 -> 0.2 | F8: =Strategie!C5 -> 0.17 | G8: =Strategie!D5 -> 0.23 | H8: 1 | I8: =M16*H8 -> 990000000 | J8: =IF(SUM(C8:C9)>I8,SUM(C8:C9)-I8,0) -> 0 | K8: =IF(SUM(J8)=0,SUM(C8:C9),I8) -> 2.8039015e+08
B9: Anlagekategorie 3 | C9: =Vermögen!D70 -> 95744169 | D9: =C9/$C$16 -> 0.080207983 | E9: =Strategie!B6 -> 0.1 | F9: =Strategie!C6 -> 0.07 | G9: =Strategie!D6 -> 0.13
B10: Anlagekategorie 4 | C10: =Vermögen!E70 -> 2.0290069e+08 | D10: =C10/$C$16 -> 0.16997646 | E10: =Strategie!B7 -> 0.12 | F10: =Strategie!C7 -> 0.08 | G10: =Strategie!D7 -> 0.16 | H10: 0.25 | I10: =M16*H10 -> 247500000 | J10: =IF(SUM(C10:C12)>I10,SUM(C10:C12)-I10,0) -> 3.2597455e+08 | K10: =SUM(C10:C12)-J10 -> 247500000
B11: Anlagekategorie 5 | C11: =Vermögen!F70 -> 2.5703629e+08 | D11: =C11/$C$16 -> 0.2153276 | E11: =Strategie!B8 -> 0.16 | F11: =Strategie!C8 -> 0.12 | G11: =Strategie!D8 -> 0.2
B12: Anlagekategorie 6 | C12: =Vermögen!G70 -> 1.1353757e+08 | D12: =C12/$C$16 -> 0.095114092 | E12: =Strategie!B9 -> 0.12 | F12: =Strategie!C9 -> 0.08 | G12: =Strategie!D9 -> 0.16
B13: Anlagekategorie 7 | C13: =Vermögen!H70 -> 1.1671205e+08 | D13: =C13/$C$16 -> 0.097773452 | E13: =Strategie!B10 -> 0.08 | F13: =Strategie!C10 -> 0.06 | G13: =Strategie!D10 -> 0.1 | H13: 0 | I13: =M16*H13 -> 0 | J13: =IF(C13>I13,C13-I13,0) -> 1.1671205e+08 | K13: =IF(J13=0,C13,I13) -> 0
B14: Anlagekategorie 8 | C14: =Vermögen!I70 -> 1.6927619e+08 | D14: =C14/$C$16 -> 0.14180813 | E14: =Strategie!B11 -> 0.16 | F14: =Strategie!C11 -> 0.13 | G14: =Strategie!D11 -> 0.19 | H14: 0.2 | I14: =M16*H14 -> 198000000 | J14: =IF(C14>I14,C14-I14,0) -> 0 | K14: =IF(J14=0,C14,I14) -> 1.6927619e+08
B15: Anlagekategorie 9 | C15: =Vermögen!J70 -> 40163036 | D15: =C15/$C$16 -> 0.033645872 | E15: =Strategie!B12 -> 0.04 | F15: =Strategie!C12 -> 0.02 | G15: =Strategie!D12 -> 0.06 | H15: 0.05 | I15: =M16*H15 -> 49500000 | J15: =IF(C15>I15,C15-I15,0) -> 0 | K15: =IF(J15=0,C15,I15) -> 40163036
B16: Total | C16: =SUM(C7:C15) -> 1.1936988e+09 | D16: =C16/$C$16 -> 1 | E16: =Strategie!B13 -> 1 | K16: =SUM(K7:K15) -> 7.5101216e+08 | L16: =K16-J17 -> 7.1876254e+08 | M16: 990000000
B17: Total Fremdwährung | C17: =C7*Strategie!L4+Lösungsraster!C8*Strategie!L5+Lösungsraster!C9*Strategie!L6+Lösungsraster!C10*Strategie!L7+Lösungsraster!C11*Strategie!L8+Lösungsraster!C12*Strategie!L9+Lösungsraster!C13*Strategie!L10+Lösungsraster!C14*Strategie!L11+Lösungsraster!C15*Strategie!L12 -> 2.3024962e+08 | D17: =C17/C16 -> 0.19288754 | H17: 0.2 | I17: =M16*H17 -> 198000000 | J17: =IF(C17>I17,C17-I17,0) -> 32249622 | K17: =I17+J17 -> 2.3024962e+08
A19: c) | B19: Annualisierte Rendite Anlagekategorien und Benchmarks seit Messbeginn
B21: 01.01.2019-30.06.2024 | C21: Annualisierte Rendite | D21: Annualisierte Rendite Benchmark
B23: Anlagekategorie 1 | C23: {=PRODUCT(1+Renditen!B4:B69)^(12/COUNT(Renditen!B4:B69))-1} -> -0.017445603 | D23: {=PRODUCT(1+Renditen!M4:M69)^(12/COUNT(Renditen!M4:M69))-1} -> -0.0012582086
B24: Anlagekategorie 2 | C24: {=PRODUCT(1+Renditen!C4:C69)^(12/COUNT(Renditen!C4:C69))-1} -> -0.00037540123 | D24: {=PRODUCT(1+Renditen!N4:N69)^(12/COUNT(Renditen!N4:N69))-1} -> -0.00072615244
B25: Anlagekategorie 3 | C25: {=PRODUCT(1+Renditen!D4:D69)^(12/COUNT(Renditen!D4:D69))-1} -> 0.0047505912 | D25: {=PRODUCT(1+Renditen!O4:O69)^(12/COUNT(Renditen!O4:O69))-1} -> -0.015684014
B26: Anlagekategorie 4 | C26: {=PRODUCT(1+Renditen!E4:E69)^(12/COUNT(Renditen!E4:E69))-1} -> 0.070229313 | D26: {=PRODUCT(1+Renditen!P4:P69)^(12/COUNT(Renditen!P4:P69))-1} -> 0.070338237
B27: Anlagekategorie 5 | C27: {=PRODUCT(1+Renditen!F4:F69)^(12/COUNT(Renditen!F4:F69))-1} -> 0.10662617 | D27: {=PRODUCT(1+Renditen!Q4:Q69)^(12/COUNT(Renditen!Q4:Q69))-1} -> 0.10588431
B28: Anlagekategorie 6 | C28: {=PRODUCT(1+Renditen!G4:G69)^(12/COUNT(Renditen!G4:G69))-1} -> -0.0017557938 | D28: {=PRODUCT(1+Renditen!R4:R69)^(12/COUNT(Renditen!R4:R69))-1} -> 0.001412617
B29: Anlagekategorie 7 | C29: {=PRODUCT(1+Renditen!H4:H69)^(12/COUNT(Renditen!H4:H69))-1} -> 0.068303714 | D29: {=PRODUCT(1+Renditen!S4:S69)^(12/COUNT(Renditen!S4:S69))-1} -> 0.16713356
B30: Anlagekategorie 8 | C30: {=PRODUCT(1+Renditen!I4:I69)^(12/COUNT(Renditen!I4:I69))-1} -> 0.052402823 | D30: {=PRODUCT(1+Renditen!T4:T69)^(12/COUNT(Renditen!T4:T69))-1} -> 0.042710876
B31: Anlagekategorie 9 | C31: {=PRODUCT(1+Renditen!J4:J69)^(12/COUNT(Renditen!J4:J69))-1} -> 0.020656016 | D31: {=PRODUCT(1+Renditen!U4:U69)^(12/COUNT(Renditen!U4:U69))-1} -> 0.029268136
A33: d) | B33: Annualisierte Rendite Gesamtvermögen und Benchmark seit Messbeginn
B35: =B21 -> 01.01.2019-30.06.2024 | C35: Rendite Gesamtvermögen | D35: Rendite Benchmark
B37: Gesamtvermögen | C37: =((1+Gesamtvermögen!V71)^(12/COUNT(Renditen!A4:A69))-1) -> 0.043829129 | D37: =(1+Gesamtvermögen!AG71)^(12/COUNT(Renditen!L4:L69))-1 -> 0.048855483
A39: e) | B39: Annualisierte Portfolio-Kennzahlen seit Messbeginn
B41: =Lösungsraster!B21 -> 01.01.2019-30.06.2024 | C41: Beta | D41: Volatilität | E41: Jensen's Alpha | F41: Tracking Error | G41: Treynor Ratio
B42: Anlagekategorie 1 | C42: =_xlfn.COVARIANCE.S(Renditen!B4:B69,Renditen!M4:M69)/_xlfn.VAR.S(Renditen!M4:M69) -> 0.44671612 | D42: =_xlfn.STDEV.S(Renditen!B4:B69)*SQRT(12) -> 0.0078428717 | E42: =C23-(Gesamtvermögen!$A$75+Lösungsraster!C42*(Lösungsraster!D23-Gesamtvermögen!$A$75)) -> -0.016798452 | F42: {=_xlfn.STDEV.S(Renditen!B4:B69-Renditen!M4:M69)*SQRT(12)} -> 0.0079007899 | G42: =(C23-Gesamtvermögen!$A$75)/Lösungsraster!C42 -> -0.038708729
B43: Anlagekategorie 2 | C43: =_xlfn.COVARIANCE.S(Renditen!C4:C69,Renditen!N4:N69)/_xlfn.VAR.S(Renditen!N4:N69) -> 1.5257547 | D43: =_xlfn.STDEV.S(Renditen!C4:C69)*SQRT(12) -> 0.054174992 | E43: =C24-(Gesamtvermögen!$A$75+Lösungsraster!C43*(Lösungsraster!D24-Gesamtvermögen!$A$75)) -> 0.00065167342 | F43: {=_xlfn.STDEV.S(Renditen!C4:C69-Renditen!N4:N69)*SQRT(12)} -> 0.02330359 | G43: =(C24-Gesamtvermögen!$A$75)/Lösungsraster!C43 -> -0.00014524694
B44: Anlagekategorie 3 | C44: =_xlfn.COVARIANCE.S(Renditen!D4:D69,Renditen!O4:O69)/_xlfn.VAR.S(Renditen!O4:O69) -> 1.1389408 | D44: =_xlfn.STDEV.S(Renditen!D4:D69)*SQRT(12) -> 0.10853165 | E44: =C25-(Gesamtvermögen!$A$75+Lösungsraster!C44*(Lösungsraster!D25-Gesamtvermögen!$A$75)) -> 0.022592386 | F44: {=_xlfn.STDEV.S(Renditen!D4:D69-Renditen!O4:O69)*SQRT(12)} -> 0.090668543 | G44: =(C25-Gesamtvermögen!$A$75)/Lösungsraster!C44 -> 0.0043060899
B45: Anlagekategorie 4 | C45: =_xlfn.COVARIANCE.S(Renditen!E4:E69,Renditen!P4:P69)/_xlfn.VAR.S(Renditen!P4:P69) -> 0.99917624 | D45: =_xlfn.STDEV.S(Renditen!E4:E69)*SQRT(12) -> 0.12831103 | E45: =C26-(Gesamtvermögen!$A$75+Lösungsraster!C45*(Lösungsraster!D26-Gesamtvermögen!$A$75)) -> -5.0854788e-05 | F45: {=_xlfn.STDEV.S(Renditen!E4:E69-Renditen!P4:P69)*SQRT(12)} -> 0.00051920615 | G45: =(C26-Gesamtvermögen!$A$75)/Lösungsraster!C45 -> 0.07044113
B46: Anlagekategorie 5 | C46: =_xlfn.COVARIANCE.S(Renditen!F4:F69,Renditen!Q4:Q69)/_xlfn.VAR.S(Renditen!Q4:Q69) -> 1.0001048 | D46: =_xlfn.STDEV.S(Renditen!F4:F69)*SQRT(12) -> 0.16911508 | E46: =C27-(Gesamtvermögen!$A$75+Lösungsraster!C46*(Lösungsraster!D27-Gesamtvermögen!$A$75)) -> 0.00073075716 | F46: {=_xlfn.STDEV.S(Renditen!F4:F69-Renditen!Q4:Q69)*SQRT(12)} -> 0.00088463526 | G46: =(C27-Gesamtvermögen!$A$75)/Lösungsraster!C46 -> 0.10676878
B47: Anlagekategorie 6 | C47: =_xlfn.COVARIANCE.S(Renditen!G4:G69,Renditen!R4:R69)/_xlfn.VAR.S(Renditen!R4:R69) -> 0.99787046 | D47: =_xlfn.STDEV.S(Renditen!G4:G69)*SQRT(12) -> 0.16120906 | E47: =C28-(Gesamtvermögen!$A$75+Lösungsraster!C47*(Lösungsraster!D28-Gesamtvermögen!$A$75)) -> -0.0031650751 | F47: {=_xlfn.STDEV.S(Renditen!G4:G69-Renditen!R4:R69)*SQRT(12)} -> 0.0043831176 | G47: =(C28-Gesamtvermögen!$A$75)/Lösungsraster!C47 -> -0.0016054226
B48: Anlagekategorie 7 | C48: =_xlfn.COVARIANCE.S(Renditen!H4:H69,Renditen!S4:S69)/_xlfn.VAR.S(Renditen!S4:S69) -> -0.037578584 | D48: =_xlfn.STDEV.S(Renditen!H4:H69)*SQRT(12) -> 0.15491909 | E48: =C29-(Gesamtvermögen!$A$75+Lösungsraster!C48*(Lösungsraster!D29-Gesamtvermögen!$A$75)) -> 0.074743926 | F48: {=_xlfn.STDEV.S(Renditen!H4:H69-Renditen!S4:S69)*SQRT(12)} -> 0.30993687 | G48: =(C29-Gesamtvermögen!$A$75)/Lösungsraster!C48 -> -1.8217159
B49: Anlagekategorie 8 | C49: =_xlfn.COVARIANCE.S(Renditen!I4:I69,Renditen!T4:T69)/_xlfn.VAR.S(Renditen!T4:T69) -> 1.1453844 | D49: =_xlfn.STDEV.S(Renditen!I4:I69)*SQRT(12) -> 0.016710812 | E49: =C30-(Gesamtvermögen!$A$75+Lösungsraster!C49*(Lösungsraster!D30-Gesamtvermögen!$A$75)) -> 0.0034600934 | F49: {=_xlfn.STDEV.S(Renditen!I4:I69-Renditen!T4:T69)*SQRT(12)} -> 0.015060255 | G49: =(C30-Gesamtvermögen!$A$75)/Lösungsraster!C49 -> 0.045885568
...

Sheet Performance
A1: Gewichte spezifisch für Performance-Berechnung | B1: 45292 | C1: 45323 | D1: 45352 | E1: 45383 | F1: 45413 | G1: 45444 | I1: Rendite BM | J1: 45292 | K1: 45323 | L1: 45352 | M1: 45383 | N1: 45413 | O1: 45444
A2: AK 1 | B2: =Vermögen!B64/Gesamtvermögen!$B62 -> 0.011462508 | C2: =Vermögen!B65/Gesamtvermögen!$B63 -> 0.011583756 | D2: =Vermögen!B66/Gesamtvermögen!$B64 -> 0.011710528 | E2: =Vermögen!B67/Gesamtvermögen!$B65 -> 0.011826031 | F2: =Vermögen!B68/Gesamtvermögen!$B66 -> 0.012056524 | G2: =Vermögen!B69/Gesamtvermögen!$B67 -> 0.01166875 | I2: AK 1 | J2: {=TRANSPOSE(Renditen!M64:U69)} -> 0.0012985335 | K2: 0.0013932071 | L2: 0.0014115728 | M2: 0.0014510154 | N2: 0.001361767 | O2: 0.0013643104
A3: AK 2 | B3: =Vermögen!C64/Gesamtvermögen!$B62 -> 0.1546839 | C3: =Vermögen!C65/Gesamtvermögen!$B63 -> 0.14996544 | D3: =Vermögen!C66/Gesamtvermögen!$B64 -> 0.15256614 | E3: =Vermögen!C67/Gesamtvermögen!$B65 -> 0.15277557 | F3: =Vermögen!C68/Gesamtvermögen!$B66 -> 0.15672903 | G3: =Vermögen!C69/Gesamtvermögen!$B67 -> 0.15480586 | I3: AK 2 | J3: 0.0031738281 | K3: 0.0048673643 | L3: -0.0022604343 | M3: 0.0071203172 | N3: 0.0089981522 | O3: 0.0074846723
A4: AK 3 | B4: =Vermögen!D64/Gesamtvermögen!$B62 -> 0.080207983 | C4: =Vermögen!D65/Gesamtvermögen!$B63 -> 0.078559989 | D4: =Vermögen!D66/Gesamtvermögen!$B64 -> 0.077621695 | E4: =Vermögen!D67/Gesamtvermögen!$B65 -> 0.075837658 | F4: =Vermögen!D68/Gesamtvermögen!$B66 -> 0.076315156 | G4: =Vermögen!D69/Gesamtvermögen!$B67 -> 0.077999558 | I4: AK 3 | J4: -0.0060847813 | K4: -0.0050030724 | L4: -0.022740408 | M4: -0.0091373002 | N4: 0.027379634 | O4: 0.027161273
A5: AK 4 | B5: =Vermögen!E64/Gesamtvermögen!$B62 -> 0.16997646 | C5: =Vermögen!E65/Gesamtvermögen!$B63 -> 0.1750366 | D5: =Vermögen!E66/Gesamtvermögen!$B64 -> 0.17375647 | E5: =Vermögen!E67/Gesamtvermögen!$B65 -> 0.17207717 | F5: =Vermögen!E68/Gesamtvermögen!$B66 -> 0.16641458 | G5: =Vermögen!E69/Gesamtvermögen!$B67 -> 0.16851491 | I5: AK 4 | J5: 0.0043938239 | K5: -0.017575452 | L5: -0.020191998 | M5: -0.052362755 | N5: 0.045542709 | O5: 0.023522883
A6: AK 5 | B6: =Vermögen!F64/Gesamtvermögen!$B62 -> 0.2153276 | C6: =Vermögen!F65/Gesamtvermögen!$B63 -> 0.21196809 | D6: =Vermögen!F66/Gesamtvermögen!$B64 -> 0.20977529 | E6: =Vermögen!F67/Gesamtvermögen!$B65 -> 0.20329523 | F6: =Vermögen!F68/Gesamtvermögen!$B66 -> 0.20158479 | G6: =Vermögen!F69/Gesamtvermögen!$B67 -> 0.21049401 | I6: AK 5 | J6: 0.025903231 | K6: -0.020711321 | L6: -0.041625411 | M6: -0.028101496 | N6: 0.078025342 | O6: 0.037668126
A7: AK 6 | B7: =Vermögen!G64/Gesamtvermögen!$B62 -> 0.095114092 | C7: =Vermögen!G65/Gesamtvermögen!$B63 -> 0.10048391 | D7: =Vermögen!G66/Gesamtvermögen!$B64 -> 0.096956777 | E7: =Vermögen!G67/Gesamtvermögen!$B65 -> 0.0986853 | F7: =Vermögen!G68/Gesamtvermögen!$B66 -> 0.096394632 | G7: =Vermögen!G69/Gesamtvermögen!$B67 -> 0.096089419 | I7: AK 6 | J7: 0.029243759 | K7: -0.043846855 | L7: 0.0086347824 | M7: -0.043844647 | N7: 0.031964829 | O7: 0.0057535791
A8: AK 7 | B8: =Vermögen!H64/Gesamtvermögen!$B62 -> 0.097773452 | C8: =Vermögen!H65/Gesamtvermögen!$B63 -> 0.10033529 | D8: =Vermögen!H66/Gesamtvermögen!$B64 -> 0.10330394 | E8: =Vermögen!H67/Gesamtvermögen!$B65 -> 0.11008651 | F8: =Vermögen!H68/Gesamtvermögen!$B66 -> 0.11174965 | G8: =Vermögen!H69/Gesamtvermögen!$B67 -> 0.10341908 | I8: AK 7 | J8: 0.033545648 | K8: 0.0039184692 | L8: 0.026013692 | M8: -0.080575052 | N8: 0.1256519 | O8: 0.054803164
A9: AK 8 | B9: =Vermögen!I64/Gesamtvermögen!$B62 -> 0.14180813 | C9: =Vermögen!I65/Gesamtvermögen!$B63 -> 0.13890762 | D9: =Vermögen!I66/Gesamtvermögen!$B64 -> 0.14076914 | E9: =Vermögen!I67/Gesamtvermögen!$B65 -> 0.14233968 | F9: =Vermögen!I68/Gesamtvermögen!$B66 -> 0.1453258 | G9: =Vermögen!I69/Gesamtvermögen!$B67 -> 0.14287819 | I9: AK 8 | J9: 0.0005456708 | K9: 0.0026255177 | L9: 0.00030583 | M9: 0.0020033757 | N9: 0.0019073259 | O9: -0.0002020001
A10: AK 9 | B10: =Vermögen!J64/Gesamtvermögen!$B62 -> 0.033645872 | C10: =Vermögen!J65/Gesamtvermögen!$B63 -> 0.033159301 | D10: =Vermögen!J66/Gesamtvermögen!$B64 -> 0.033540011 | E10: =Vermögen!J67/Gesamtvermögen!$B65 -> 0.033076864 | F10: =Vermögen!J68/Gesamtvermögen!$B66 -> 0.033429831 | G10: =Vermögen!J69/Gesamtvermögen!$B67 -> 0.034130208 | I10: AK 9 | J10: 0.029374692 | K10: -0.028217005 | L10: -0.058072646 | M10: -0.04571628 | N10: 0.088559761 | O10: 0.081410974
I11: GV | J11: =Gesamtvermögen!AF63 -> 0.012179232 | K11: =Gesamtvermögen!AF64 -> -0.010578578 | L11: =Gesamtvermögen!AF65 -> -0.010937706 | M11: =Gesamtvermögen!AF66 -> -0.023455889 | N11: =Gesamtvermögen!AF67 -> 0.040249503 | O11: =Gesamtvermögen!AF68 -> 0.021388796
I13: Renditen | J13: 45292 | K13: 45323 | L13: 45352 | M13: 45383 | N13: 45413 | O13: 45444
I14: AK 1 | J14: {=TRANSPOSE(Renditen!B64:J69)} -> 0.00056459464 | K14: 0.00046832307 | L14: -0.00087992775 | M14: -0.0010584952 | N14: -0.0007382656 | O14: -0.0032351343
I15: AK 2 | J15: 0.0012 | K15: 0.0068 | L15: -0.00928 | M15: 0.0052 | N15: 0.0198 | O15: 0.0139
I16: AK 3 | J16: 0.016226221 | K16: -0.022182169 | L16: -0.033377357 | M16: -0.013986602 | N16: 0.055257398 | O16: 0.043428889
I17: AK 4 | J17: 0.0044 | K17: -0.0176 | L17: -0.0202 | M17: -0.0524 | N17: 0.0455 | O17: 0.0235
I18: AK 5 | J18: 0.0262 | K18: -0.0206 | L18: -0.0412 | M18: -0.0284 | N18: 0.0781 | O18: 0.038
I19: AK 6 | J19: 0.0297 | K19: -0.0451 | L19: 0.007 | M19: -0.0429 | N19: 0.0292 | O19: 0.0044
I20: AK 7 | J20: -0.032145346 | K20: 0.018918505 | L20: 0.054319823 | M20: -0.0053529211 | N20: -0.044498089 | O20: -0.040692859
I21: AK 8 | J21: 0.0029 | K21: 0.0029 | L21: 0.0004 | M21: 0.0004 | N21: 0.01508 | O21: 0.0071
I22: AK 9 | J22: -0.00312 | K22: 0.001 | L22: -0.0243 | M22: -0.0097 | N22: 0.0541 | O22: 0.0003

Sheet Gesamtvermögen
A1: Datum | B1: Summe Vermögen | C1: Gewicht 1 | D1: Gewicht 2 | E1: Gewicht 3 | F1: Gewicht 4 | G1: Gewicht 5 | H1: Gewicht 6 | I1: Gewicht 7 | J1: Gewicht 8 | K1: Gewicht 9 | L1: Gew. Rendite 1 | M1: Gew. Rendite 2 | N1: Gew. Rendite 3 | O1: Gew. Rendite 4 | P1: Gew. Rendite 5 | Q1: Gew. Rendite 6 | R1: Gew. Rendite 7 | S1: Gew. Rendite 8 | T1: Gew. Rendite 9 | U1: Gew. Rendite Gesamtvermögen | W1: Benchmark Gew. Rendite 1 | X1: Benchmark Gew. Rendite 2 | Y1: Benchmark Gew. Rendite 3 | Z1: Benchmark Gew. Rendite 4 | AA1: Benchmark Gew. Rendite 5 | AB1: Benchmark Gew. Rendite 6 | AC1: Benchmark Gew. Rendite 7 | AD1: Benchmark Gew. Rendite 8 | AE1: Benchmark Gew. Rendite 9 | AF1: Benchmark Gew. Rendite Gesamtvermögen
A2: =Vermögen!A4 -> 43465 | B2: =SUM(Vermögen!B4:J4) -> 973813300 | C2: =Vermögen!B4/Gesamtvermögen!$B2 -> 0.015403363 | D2: =Vermögen!C4/Gesamtvermögen!$B2 -> 0.19721439 | E2: =Vermögen!D4/Gesamtvermögen!$B2 -> 0.099890811 | F2: =Vermögen!E4/Gesamtvermögen!$B2 -> 0.14062244 | G2: =Vermögen!F4/Gesamtvermögen!$B2 -> 0.15840819 | H2: =Vermögen!G4/Gesamtvermögen!$B2 -> 0.11532498 | I2: =Vermögen!H4/Gesamtvermögen!$B2 -> 0.078994916 | J2: =Vermögen!I4/Gesamtvermögen!$B2 -> 0.15667069 | K2: =Vermögen!J4/Gesamtvermögen!$B2 -> 0.037470221
A3: =Vermögen!A5 -> 43496 | B3: =SUM(Vermögen!B5:J5) -> 1.0121515e+09 | C3: =Vermögen!B5/Gesamtvermögen!$B3 -> 0.01482288 | D3: =Vermögen!C5/Gesamtvermögen!$B3 -> 0.19088279 | E3: =Vermögen!D5/Gesamtvermögen!$B3 -> 0.10042705 | F3: =Vermögen!E5/Gesamtvermögen!$B3 -> 0.14468549 | G3: =Vermögen!F5/Gesamtvermögen!$B3 -> 0.16322899 | H3: =Vermögen!G5/Gesamtvermögen!$B3 -> 0.12143102 | I3: =Vermögen!H5/Gesamtvermögen!$B3 -> 0.076478769 | J3: =Vermögen!I5/Gesamtvermögen!$B3 -> 0.15124883 | K3: =Vermögen!J5/Gesamtvermögen!$B3 -> 0.036794174 | L3: =C2*Renditen!B4 -> 3.0806727e-06 | M3: =D2*Renditen!C4 -> 0.0011832864 | N3: =E2*Renditen!D4 -> 0.0044899679 | O3: =F2*Renditen!E4 -> 0.0097591972 | P3: =G2*Renditen!F4 -> 0.011246981 | Q3: =H2*Renditen!G4 -> 0.010886678 | R3: =I2*Renditen!H4 -> 0.00049475608 | S3: =J2*Renditen!I4 -> 0.00053268034 | T3: =K2*Renditen!J4 -> 0.00077250711 | U3: =SUM(L3:T3) -> 0.039369135 | W3: =Renditen!M4*Strategie!$B$4 -> -1.5096376e-05 | X3: =Strategie!$B$5*Renditen!N4 -> 0.0006574421 | Y3: =Strategie!$B$6*Renditen!O4 -> 0.00060515221 | Z3: =Strategie!$B$7*Renditen!P4 -> 0.0083534383 | AA3: =Strategie!$B$8*Renditen!Q4 -> 0.011390439 | AB3: =Strategie!$B$9*Renditen!R4 -> 0.011340987 | AC3: =Strategie!$B$10*Renditen!S4 -> 0.009004337 | AD3: =Strategie!$B$11*Renditen!T4 -> 0.00051203318 | AE3: =Strategie!$B$12*Renditen!U4 -> 0.0040862188 | AF3: =SUM(W3:AE3) -> 0.045934951
A4: =Vermögen!A6 -> 43524 | B4: =SUM(Vermögen!B6:J6) -> 1.0266599e+09 | C4: =Vermögen!B6/Gesamtvermögen!$B4 -> 0.014591488 | D4: =Vermögen!C6/Gesamtvermögen!$B4 -> 0.18816648 | E4: =Vermögen!D6/Gesamtvermögen!$B4 -> 0.099661032 | F4: =Vermögen!E6/Gesamtvermögen!$B4 -> 0.14874587 | G4: =Vermögen!F6/Gesamtvermögen!$B4 -> 0.16591088 | H4: =Vermögen!G6/Gesamtvermögen!$B4 -> 0.12048118 | I4: =Vermögen!H6/Gesamtvermögen!$B4 -> 0.075546124 | J4: =Vermögen!I6/Gesamtvermögen!$B4 -> 0.14961841 | K4: =Vermögen!J6/Gesamtvermögen!$B4 -> 0.037278532 | L4: =C3*Renditen!B5 -> -2.223432e-05 | M4: =D3*Renditen!C5 -> -1.9088279e-05 | N4: =E3*Renditen!D5 -> 0.00066254447 | O4: =F3*Renditen!E5 -> 0.0061925391 | P4: =G3*Renditen!F5 -> 0.0050600985 | Q4: =H3*Renditen!G5 -> 0.00077715856 | R4: =I3*Renditen!H5 -> 0.00015025079 | S4: =J3*Renditen!I5 -> 0.00051424603 | T4: =K3*Renditen!J5 -> 0.0010187177 | U4: =SUM(L4:T4) -> 0.014334233 | W4: =Renditen!M5*Strategie!$B$4 -> -1.3290692e-05 | X4: =Strategie!$B$5*Renditen!N5 -> 0.00018287108 | Y4: =Strategie!$B$6*Renditen!O5 -> -0.00034903096 | Z4: =Strategie!$B$7*Renditen!P5 -> 0.0051370936 | AA4: =Strategie!$B$8*Renditen!Q5 -> 0.0049626555 | AB4: =Strategie!$B$9*Renditen!R5 -> 0.00076675712 | AC4: =Strategie!$B$10*Renditen!S5 -> 0.0024961767 | AD4: =Strategie!$B$11*Renditen!T5 -> 0.00046413822 | AE4: =Strategie!$B$12*Renditen!U5 -> 6.8657028e-05 | AF4: =SUM(W4:AE4) -> 0.013716028
A5: =Vermögen!A7 -> 43555 | B5: =SUM(Vermögen!B7:J7) -> 1.036746e+09 | C5: =Vermögen!B7/Gesamtvermögen!$B5 -> 0.014436529 | D5: =Vermögen!C7/Gesamtvermögen!$B5 -> 0.18887005 | E5: =Vermögen!D7/Gesamtvermögen!$B5 -> 0.099330825 | F5: =Vermögen!E7/Gesamtvermögen!$B5 -> 0.15098126 | G5: =Vermögen!F7/Gesamtvermögen!$B5 -> 0.16658053 | H5: =Vermögen!G7/Gesamtvermögen!$B5 -> 0.1202874 | I5: =Vermögen!H7/Gesamtvermögen!$B5 -> 0.073973886 | J5: =Vermögen!I7/Gesamtvermögen!$B5 -> 0.14866659 | K5: =Vermögen!J7/Gesamtvermögen!$B5 -> 0.036872934 | L5: =C4*Renditen!B6 -> -1.3132339e-05 | M5: =D4*Renditen!C6 -> 0.0025590641 | N5: =E4*Renditen!D6 -> 0.00064563477 | O5: =F4*Renditen!E6 -> 0.0037186468 | P5: =G4*Renditen!F6 -> 0.0023061612 | Q5: =H4*Renditen!G6 -> 0.00098794566 | R5: =I4*Renditen!H6 -> -0.00084550647 | S5: =J4*Renditen!I6 -> 0.00050870261 | T5: =K4*Renditen!J6 -> -4.3352599e-05 | U5: =SUM(L5:T5) -> 0.0098241638 | W5: =Renditen!M6*Strategie!$B$4 -> -1.4477092e-05 | X5: =Strategie!$B$5*Renditen!N6 -> 0.0013855055 | Y5: =Strategie!$B$6*Renditen!O6 -> 0.0016110281 | Z5: =Strategie!$B$7*Renditen!P6 -> 0.0030286581 | AA5: =Strategie!$B$8*Renditen!Q6 -> 0.0021785575 | AB5: =Strategie!$B$9*Renditen!R6 -> 0.00097059632 | AC5: =Strategie!$B$10*Renditen!S6 -> 0.00039616277 | AD5: =Strategie!$B$11*Renditen!T6 -> 0.00064598888 | AE5: =Strategie!$B$12*Renditen!U6 -> 0.0014704813 | AF5: =SUM(W5:AE5) -> 0.011672501
A6: =Vermögen!A8 -> 43585 | B6: =SUM(Vermögen!B8:J8) -> 1.0569386e+09 | C6: =Vermögen!B8/Gesamtvermögen!$B6 -> 0.01418621 | D6: =Vermögen!C8/Gesamtvermögen!$B6 -> 0.18459478 | E6: =Vermögen!D8/Gesamtvermögen!$B6 -> 0.097545512 | F6: =Vermögen!E8/Gesamtvermögen!$B6 -> 0.15459823 | G6: =Vermögen!F8/Gesamtvermögen!$B6 -> 0.16932938 | H6: =Vermögen!G8/Gesamtvermögen!$B6 -> 0.12325165 | I6: =Vermögen!H8/Gesamtvermögen!$B6 -> 0.074152929 | J6: =Vermögen!I8/Gesamtvermögen!$B6 -> 0.14632215 | K6: =Vermögen!J8/Gesamtvermögen!$B6 -> 0.036019159 | L6: =C5*Renditen!B7 -> 2.5985752e-05 | M6: =D5*Renditen!C7 -> -0.00067993219 | N6: =E5*Renditen!D7 -> 0.00011457595 | O6: =F5*Renditen!E7 -> 0.0066280771 | P6: =G5*Renditen!F7 -> 0.0060468731 | Q6: =H5*Renditen!G7 -> 0.0053648181 | R6: =I5*Renditen!H7 -> 0.0016233154 | S6: =J5*Renditen!I7 -> 0.00050546641 | T6: =K5*Renditen!J7 -> -0.00015223126 | U6: =SUM(L6:T6) -> 0.019476948 | W6: =Renditen!M7*Strategie!$B$4 -> -1.3343824e-05 | X6: =Strategie!$B$5*Renditen!N7 -> -0.00021168822 | Y6: =Strategie!$B$6*Renditen!O7 -> -0.00046166127 | Z6: =Strategie!$B$7*Renditen!P7 -> 0.0052731428 | AA6: =Strategie!$B$8*Renditen!Q7 -> 0.0058268341 | AB6: =Strategie!$B$9*Renditen!R7 -> 0.0053684289 | AC6: =Strategie!$B$10*Renditen!S7 -> 0.007217322 | AD6: =Strategie!$B$11*Renditen!T7 -> 0.00049223614 | AE6: =Strategie!$B$12*Renditen!U7 -> -0.00051084289 | AF6: =SUM(W6:AE6) -> 0.022980428
A7: =Vermögen!A9 -> 43616 | B7: =SUM(Vermögen!B9:J9) -> 1.033782e+09 | C7: =Vermögen!B9/Gesamtvermögen!$B7 -> 0.014483674 | D7: =Vermögen!C9/Gesamtvermögen!$B7 -> 0.19152288 | E7: =Vermögen!D9/Gesamtvermögen!$B7 -> 0.099479743 | F7: =Vermögen!E9/Gesamtvermögen!$B7 -> 0.15550062 | G7: =Vermögen!F9/Gesamtvermögen!$B7 -> 0.16271768 | H7: =Vermögen!G9/Gesamtvermögen!$B7 -> 0.11542743 | I7: =Vermögen!H9/Gesamtvermögen!$B7 -> 0.074836252 | J7: =Vermögen!I9/Gesamtvermögen!$B7 -> 0.15010839 | K7: =Vermögen!J9/Gesamtvermögen!$B7 -> 0.035923341 | L7: =C6*Renditen!B8 -> -1.9860695e-05 | M7: =D6*Renditen!C8 -> 0.0027320027 | N7: =E6*Renditen!D8 -> -0.000245282 | O7: =F6*Renditen!E8 -> -0.0025044913 | P7: =G6*Renditen!F8 -> -0.010176696 | Q7: =H6*Renditen!G8 -> -0.010353139 | R7: =I6*Renditen!H8 -> -0.00095627267 | S7: =J6*Renditen!I8 -> 0.00049749531 | T7: =K6*Renditen!J8 -> -0.00088286672 | U7: =SUM(L7:T7) -> -0.02190911 | W7: =Renditen!M8*Strategie!$B$4 -> -1.3560826e-05 | X7: =Strategie!$B$5*Renditen!N8 -> 0.0014077045 | Y7: =Strategie!$B$6*Renditen!O8 -> 0.0014759133 | Z7: =Strategie!$B$7*Renditen!P8 -> -0.0019492193 | AA7: =Strategie!$B$8*Renditen!Q8 -> -0.0095613907 | AB7: =Strategie!$B$9*Renditen!R8 -> -0.010143743 | AC7: =Strategie!$B$10*Renditen!S8 -> -0.0042172603 | AD7: =Strategie!$B$11*Renditen!T8 -> 0.00059823651 | AE7: =Strategie!$B$12*Renditen!U8 -> -0.00015625 | AF7: =SUM(W7:AE7) -> -0.022559569
A8: =Vermögen!A10 -> 43646 | B8: =SUM(Vermögen!B10:J10) -> 1.0567084e+09 | C8: =Vermögen!B10/Gesamtvermögen!$B8 -> 0.014095756 | D8: =Vermögen!C10/Gesamtvermögen!$B8 -> 0.18815454 | E8: =Vermögen!D10/Gesamtvermögen!$B8 -> 0.10025954 | F8: =Vermögen!E10/Gesamtvermögen!$B8 -> 0.15787728 | G8: =Vermögen!F10/Gesamtvermögen!$B8 -> 0.16813369 | H8: =Vermögen!G10/Gesamtvermögen!$B8 -> 0.11618659 | I8: =Vermögen!H10/Gesamtvermögen!$B8 -> 0.07267136 | J8: =Vermögen!I10/Gesamtvermögen!$B8 -> 0.14735093 | K8: =Vermögen!J10/Gesamtvermögen!$B8 -> 0.035270302 | L8: =C7*Renditen!B9 -> -7.5315105e-05 | M8: =D7*Renditen!C9 -> 0.00080439608 | N8: =E7*Renditen!D9 -> 0.0030032694 | O8: =F7*Renditen!E9 -> 0.0058779234 | P8: =G7*Renditen!F9 -> 0.0091447338 | Q8: =H7*Renditen!G9 -> 0.0033358526 | R8: =I7*Renditen!H9 -> -0.00055324922 | S8: =J7*Renditen!I9 -> 0.00051036851 | T8: =K7*Renditen!J9 -> 0.00012915525 | U8: =SUM(L8:T8) -> 0.022177135 | W8: =Renditen!M9*Strategie!$B$4 -> -1.3066792e-05 | X8: =Strategie!$B$5*Renditen!N9 -> 0.00037577032 | Y8: =Strategie!$B$6*Renditen!O9 -> 0.0011099919 | Z8: =Strategie!$B$7*Renditen!P9 -> 0.0044991658 | AA8: =Strategie!$B$8*Renditen!Q9 -> 0.0089669544 | AB8: =Strategie!$B$9*Renditen!R9 -> 0.0035793417 | AC8: =Strategie!$B$10*Renditen!S9 -> 0.0036525021 | AD8: =Strategie!$B$11*Renditen!T9 -> 0.00055806725 | AE8: =Strategie!$B$12*Renditen!U9 -> 0.00031983702 | AF8: =SUM(W8:AE8) -> 0.023048564
A9: =Vermögen!A11 -> 43677 | B9: =SUM(Vermögen!B11:J11) -> 1.0660559e+09 | C9: =Vermögen!B11/Gesamtvermögen!$B9 -> 0.013965173 | D9: =Vermögen!C11/Gesamtvermögen!$B9 -> 0.18932096 | E9: =Vermögen!D11/Gesamtvermögen!$B9 -> 0.10044427 | F9: =Vermögen!E11/Gesamtvermögen!$B9 -> 0.157651 | G9: =Vermögen!F11/Gesamtvermögen!$B9 -> 0.1682927 | H9: =Vermögen!G11/Gesamtvermögen!$B9 -> 0.11546726 | I9: =Vermögen!H11/Gesamtvermögen!$B9 -> 0.073118072 | J9: =Vermögen!I11/Gesamtvermögen!$B9 -> 0.1465555 | K9: =Vermögen!J11/Gesamtvermögen!$B9 -> 0.035185074 | L9: =C8*Renditen!B10 -> -7.0478778e-06 | M9: =D8*Renditen!C10 -> 0.0028411336 | N9: =E8*Renditen!D10 -> 0.0010732475 | O9: =F8*Renditen!E10 -> 0.0011682919 | P9: =G8*Renditen!F10 -> 0.0016477102 | Q9: =H8*Renditen!G10 -> 0.00030208514 | R9: =I8*Renditen!H10 -> 0.0010935099 | S9: =J8*Renditen!I10 -> 0.00050099317 | T9: =K8*Renditen!J10 -> 0.0002260171 | U9: =SUM(L9:T9) -> 0.0088459405 | W9: =Renditen!M10*Strategie!$B$4 -> -1.354417e-05 | X9: =Strategie!$B$5*Renditen!N10 -> 0.0015752757 | Y9: =Strategie!$B$6*Renditen!O10 -> 0.00049914369 | Z9: =Strategie!$B$7*Renditen!P10 -> 0.00087234437 | AA9: =Strategie!$B$8*Renditen!Q10 -> 0.0015780644 | AB9: =Strategie!$B$9*Renditen!R10 -> 0.00035618326 | AC9: =Strategie!$B$10*Renditen!S10 -> 0.0021589736 | AD9: =Strategie!$B$11*Renditen!T10 -> 0.00062290045 | AE9: =Strategie!$B$12*Renditen!U10 -> 0.00035165724 | AF9: =SUM(W9:AE9) -> 0.0080009985
A10: =Vermögen!A12 -> 43708 | B10: =SUM(Vermögen!B12:J12) -> 1.0620295e+09 | C10: =Vermögen!B12/Gesamtvermögen!$B10 -> 0.014009707 | D10: =Vermögen!C12/Gesamtvermögen!$B10 -> 0.19452363 | E10: =Vermögen!D12/Gesamtvermögen!$B10 -> 0.10125403 | F10: =Vermögen!E12/Gesamtvermögen!$B10 -> 0.15820122 | G10: =Vermögen!F12/Gesamtvermögen!$B10 -> 0.16512979 | H10: =Vermögen!G12/Gesamtvermögen!$B10 -> 0.11008659 | I10: =Vermögen!H12/Gesamtvermögen!$B10 -> 0.073448448 | J10: =Vermögen!I12/Gesamtvermögen!$B10 -> 0.14761131 | K10: =Vermögen!J12/Gesamtvermögen!$B10 -> 0.035735271 | L10: =C9*Renditen!B11 -> -8.3791035e-06 | M10: =D9*Renditen!C11 -> 0.0044679746 | N10: =E9*Renditen!D11 -> 0.0004273328 | O10: =F9*Renditen!E11 -> -4.7295299e-05 | P10: =G9*Renditen!F11 -> -0.0037865857 | Q10: =H9*Renditen!G11 -> -0.0057964565 | R10: =I9*Renditen!H11 -> 5.2967228e-05 | S10: =J9*Renditen!I11 -> 0.00049828871 | T10: =K9*Renditen!J11 -> 0.00041522732 | U10: =SUM(L10:T10) -> -0.0037769259 | W10: =Renditen!M11*Strategie!$B$4 -> -1.4196264e-05 | X10: =Strategie!$B$5*Renditen!N11 -> 0.0016225067 | Y10: =Strategie!$B$6*Renditen!O11 -> 0.002603982 | Z10: =Strategie!$B$7*Renditen!P11 -> -3.5111424e-05 | AA10: =Strategie!$B$8*Renditen!Q11 -> -0.0035788991 | AB10: =Strategie!$B$9*Renditen!R11 -> -0.0059141696 | AC10: =Strategie!$B$10*Renditen!S11 -> -8.382592e-05 | AD10: =Strategie!$B$11*Renditen!T11 -> 0.00059910725 | AE10: =Strategie!$B$12*Renditen!U11 -> 0.00072923971 | AF10: =SUM(W10:AE10) -> -0.0040713668
A11: =Vermögen!A13 -> 43738 | B11: =SUM(Vermögen!B13:J13) -> 1.0709737e+09 | C11: =Vermögen!B13/Gesamtvermögen!$B11 -> 0.013880202 | D11: =Vermögen!C13/Gesamtvermögen!$B11 -> 0.1892147 | E11: =Vermögen!D13/Gesamtvermögen!$B11 -> 0.099613046 | F11: =Vermögen!E13/Gesamtvermögen!$B11 -> 0.1591077 | G11: =Vermögen!F13/Gesamtvermögen!$B11 -> 0.16725498 | H11: =Vermögen!G13/Gesamtvermögen!$B11 -> 0.11212564 | I11: =Vermögen!H13/Gesamtvermögen!$B11 -> 0.075896202 | J11: =Vermögen!I13/Gesamtvermögen!$B11 -> 0.14687623 | K11: =Vermögen!J13/Gesamtvermögen!$B11 -> 0.036031303 | L11: =C10*Renditen!B12 -> -1.2608736e-05 | M11: =D10*Renditen!C12 -> -0.0037154014 | N11: =E10*Renditen!D12 -> -0.00080205961 | O11: =F10*Renditen!E12 -> 0.0022464573 | P11: =G10*Renditen!F12 -> 0.0035337776 | Q11: =H10*Renditen!G12 -> 0.0029833467 | R11: =I10*Renditen!H12 -> 0.0030869368 | S11: =J10*Renditen!I12 -> 0.00050187845 | T11: =K10*Renditen!J12 -> 0.00059948121 | U11: =SUM(L11:T11) -> 0.0084218083 | W11: =Renditen!M12*Strategie!$B$4 -> -1.4901886e-05 | X11: =Strategie!$B$5*Renditen!N12 -> -0.0022148394 | Y11: =Strategie!$B$6*Renditen!O12 -> -0.00088296001 | Z11: =Strategie!$B$7*Renditen!P12 -> 0.0017134016 | AA11: =Strategie!$B$8*Renditen!Q12 -> 0.0034485851 | AB11: =Strategie!$B$9*Renditen!R12 -> 0.0032423853 | AC11: =Strategie!$B$10*Renditen!S12 -> 0.0023707389 | AD11: =Strategie!$B$11*Renditen!T12 -> 0.0009479295 | AE11: =Strategie!$B$12*Renditen!U12 -> 0.0010054107 | AF11: =SUM(W11:AE11) -> 0.0096157499
A12: =Vermögen!A14 -> 43769 | B12: =SUM(Vermögen!B14:J14) -> 1.0758208e+09 | C12: =Vermögen!B14/Gesamtvermögen!$B12 -> 0.013807993 | D12: =Vermögen!C14/Gesamtvermögen!$B12 -> 0.1852919 | E12: =Vermögen!D14/Gesamtvermögen!$B12 -> 0.099167303 | F12: =Vermögen!E14/Gesamtvermögen!$B12 -> 0.15973717 | G12: =Vermögen!F14/Gesamtvermögen!$B12 -> 0.16929865 | H12: =Vermögen!G14/Gesamtvermögen!$B12 -> 0.11521464 | I12: =Vermögen!H14/Gesamtvermögen!$B12 -> 0.074741334 | J12: =Vermögen!I14/Gesamtvermögen!$B12 -> 0.14671161 | K12: =Vermögen!J14/Gesamtvermögen!$B12 -> 0.036029394 | L12: =C11*Renditen!B13 -> -9.7161413e-06 | M12: =D11*Renditen!C13 -> -0.0030841996 | N12: =E11*Renditen!D13 -> 3.0714132e-06 | O12: =F11*Renditen!E13 -> 0.0013524154 | P12: =G11*Renditen!F13 -> 0.0028098837 | Q12: =H11*Renditen!G13 -> 0.0036104456 | R12: =I11*Renditen!H13 -> -0.00081660126 | S12: =J11*Renditen!I13 -> 0.00049937917 | T12: =K11*Renditen!J13 -> 0.0001611537 | U12: =SUM(L12:T12) -> 0.004525832 | W12: =Renditen!M13*Strategie!$B$4 -> -1.6026686e-05 | X12: =Strategie!$B$5*Renditen!N13 -> -0.0015677492 | Y12: =Strategie!$B$6*Renditen!O13 -> -0.00067994627 | Z12: =Strategie!$B$7*Renditen!P13 -> 0.0010193957 | AA12: =Strategie!$B$8*Renditen!Q13 -> 0.0026972958 | AB12: =Strategie!$B$9*Renditen!R13 -> 0.0037557469 | AC12: =Strategie!$B$10*Renditen!S13 -> 0.0015106045 | AD12: =Strategie!$B$11*Renditen!T13 -> 0.00056832003 | AE12: =Strategie!$B$12*Renditen!U13 -> 0.00067942997 | AF12: =SUM(W12:AE12) -> 0.0079670708
A13: =Vermögen!A15 -> 43799 | B13: =SUM(Vermögen!B15:J15) -> 1.089851e+09 | C13: =Vermögen!B15/Gesamtvermögen!$B13 -> 0.013624783 | D13: =Vermögen!C15/Gesamtvermögen!$B13 -> 0.18436979 | E13: =Vermögen!D15/Gesamtvermögen!$B13 -> 0.097314351 | F13: =Vermögen!E15/Gesamtvermögen!$B13 -> 0.16201701 | G13: =Vermögen!F15/Gesamtvermögen!$B13 -> 0.17216617 | H13: =Vermögen!G15/Gesamtvermögen!$B13 -> 0.11500521 | I13: =Vermögen!H15/Gesamtvermögen!$B13 -> 0.074716067 | J13: =Vermögen!I15/Gesamtvermögen!$B13 -> 0.14531531 | K13: =Vermögen!J15/Gesamtvermögen!$B13 -> 0.035471303 | L13: =C12*Renditen!B14 -> -5.5231973e-06 | M13: =D12*Renditen!C14 -> 0.0014823352 | N13: =E12*Renditen!D14 -> -0.00058383349 | O13: =F12*Renditen!E14 -> 0.0043927722 | P13: =G12*Renditen!F14 -> 0.0051128192 | Q13: =H12*Renditen!G14 -> 0.001290404 | R13: =I12*Renditen!H14 -> 0.00094913812 | S13: =J12*Renditen!I14 -> 0.00049881948 | T13: =K12*Renditen!J14 -> -9.549471e-05 | U13: =SUM(L13:T13) -> 0.013041437 | W13: =Renditen!M14*Strategie!$B$4 -> -1.5447418e-05 | X13: =Strategie!$B$5*Renditen!N14 -> 0.00076749436 | Y13: =Strategie!$B$6*Renditen!O14 -> -0.00063015328 | Z13: =Strategie!$B$7*Renditen!P14 -> 0.0032979683 | AA13: =Strategie!$B$8*Renditen!Q14 -> 0.0048422225 | AB13: =Strategie!$B$9*Renditen!R14 -> 0.0013649386 | AC13: =Strategie!$B$10*Renditen!S14 -> 0.0029787165 | AD13: =Strategie!$B$11*Renditen!T14 -> 0.00060667672 | AE13: =Strategie!$B$12*Renditen!U14 -> -0.00039443265 | AF13: =SUM(W13:AE13) -> 0.012817984
A14: =Vermögen!A16 -> 43830 | B14: =SUM(Vermögen!B16:J16) -> 1.1002252e+09 | C14: =Vermögen!B16/Gesamtvermögen!$B14 -> 0.013447727 | D14: =Vermögen!C16/Gesamtvermögen!$B14 -> 0.18053109 | E14: =Vermögen!D16/Gesamtvermögen!$B14 -> 0.098110096 | F14: =Vermögen!E16/Gesamtvermögen!$B14 -> 0.16252755 | G14: =Vermögen!F16/Gesamtvermögen!$B14 -> 0.17397071 | H14: =Vermögen!G16/Gesamtvermögen!$B14 -> 0.11865993 | I14: =Vermögen!H16/Gesamtvermögen!$B14 -> 0.071432561 | J14: =Vermögen!I16/Gesamtvermögen!$B14 -> 0.14626264 | K14: =Vermögen!J16/Gesamtvermögen!$B14 -> 0.035057703 | L14: =C13*Renditen!B15 -> -4.9049219e-05 | M14: =D13*Renditen!C15 -> -0.0021202526 | N14: =E13*Renditen!D15 -> 0.0017296407 | O14: =F13*Renditen!E15 -> 0.002057616 | P14: =G13*Renditen!F15 -> 0.0034605401 | Q14: =H13*Renditen!G15 -> 0.0047842169 | R14: =I13*Renditen!H15 -> -0.0026035509 | S14: =J13*Renditen!I15 -> 0.0023395765 | T14: =K13*Renditen!J15 -> -7.9891134e-05 | U14: =SUM(L14:T14) -> 0.0095188463 | W14: =Renditen!M15*Strategie!$B$4 -> -1.4779634e-05 | X14: =Strategie!$B$5*Renditen!N15 -> -0.0011543363 | Y14: =Strategie!$B$6*Renditen!O15 -> -0.00087916347 | Z14: =Strategie!$B$7*Renditen!P15 -> 0.0015278189 | AA14: =Strategie!$B$8*Renditen!Q15 -> 0.0032504682 | AB14: =Strategie!$B$9*Renditen!R15 -> 0.0049525266 | AC14: =Strategie!$B$10*Renditen!S15 -> 0.00064488422 | AD14: =Strategie!$B$11*Renditen!T15 -> 0.0014881501 | AE14: =Strategie!$B$12*Renditen!U15 -> -0.00013723435 | AF14: =SUM(W14:AE14) -> 0.0096783344
... A68: =Vermögen!A70 -> 45473 | B68: =SUM(Vermögen!B70:J70) -> 1.1936988e+09 | C68: =Vermögen!B70/Gesamtvermögen!$B68 -> 0.011462508 | D68: =Vermögen!C70/Gesamtvermögen!$B68 -> 0.1546839 | E68: =Vermögen!D70/Gesamtvermögen!$B68 -> 0.080207983 | F68: =Vermögen!E70/Gesamtvermögen!$B68 -> 0.16997646 | G68: =Vermögen!F70/Gesamtvermögen!$B68 -> 0.2153276 | H68: =Vermögen!G70/Gesamtvermögen!$B68 -> 0.095114092 | I68: =Vermögen!H70/Gesamtvermögen!$B68 -> 0.097773452 | J68: =Vermögen!I70/Gesamtvermögen!$B68 -> 0.14180813 | K68: =Vermögen!J70/Gesamtvermögen!$B68 -> 0.033645872 | L68: =C67*Renditen!B69 -> -3.7749972e-05 | M68: =D67*Renditen!C69 -> 0.0021518015 | N68: =E67*Renditen!D69 -> 0.0033874341 | O68: =F67*Renditen!E69 -> 0.0039601005 | P68: =G67*Renditen!F69 -> 0.0079987726 | Q68: =H67*Renditen!G69 -> 0.00042279345 | R68: =I67*Renditen!H69 -> -0.0042084181 | S68: =J67*Renditen!I69 -> 0.0010144351 | T68: =K67*Renditen!J69 -> 1.0239062e-05 | U68: =SUM(L68:T68) -> 0.014699408 | W68: =Renditen!M69*Strategie!$B$4 -> 2.7286208e-05 | X68: =Strategie!$B$5*Renditen!N69 -> 0.0014969345 | Y68: =Strategie!$B$6*Renditen!O69 -> 0.0027161273 | Z68: =Strategie!$B$7*Renditen!P69 -> 0.002822746 | AA68: =Strategie!$B$8*Renditen!Q69 -> 0.0060269002 | AB68: =Strategie!$B$9*Renditen!R69 -> 0.00069042949 | AC68: =Strategie!$B$10*Renditen!S69 -> 0.0043842531 | AD68: =Strategie!$B$11*Renditen!T69 -> -3.2320016e-05 | AE68: =Strategie!$B$12*Renditen!U69 -> 0.003256439 | AF68: =SUM(W68:AE68) -> 0.021388796
V70: Kumulierte Rendite Gesamtvermögen | AG70: Kumulierte Rendite Gesamtvermögen Benchmark
V71: {=PRODUCT(1+U3:U68)-1} -> 0.2660818 | AG71: {=PRODUCT(1+AF3:AF68)-1} -> 0.29997827
A72: Kumulierte Rendite Risikoloser Zinssatz
A73: {=PRODUCT(1+Renditen!W4:W69)-1} -> -0.00084555251
A74: Annualisierter Risikoloser Zinssatz
A75: =(1+A73)^(12/COUNT(Renditen!L4:L69))-1 -> -0.00015379003

Sheet Kumulative Renditen
A1: T | B1: AK 1 | C1: AK 2 | D1: AK 3 | E1: AK 4 | F1: AK 5 | G1: AK 6 | H1: AK 7 | I1: AK 8 | J1: AK 9 | L1: B | M1: AK 1 | N1: AK 2 | O1: AK 3 | P1: AK 4 | Q1: AK 5 | R1: AK 6 | S1: AK 7 | T1: AK 8 | U1: AK 9
A2: 43466 | B2: =PRODUCT(1+Renditen!B4)-1 -> 0.0002 | C2: =PRODUCT(1+Renditen!C4)-1 -> 0.006 | D2: =PRODUCT(1+Renditen!D4)-1 -> 0.044948758 | E2: =PRODUCT(1+Renditen!E4)-1 -> 0.0694 | F2: =PRODUCT(1+Renditen!F4)-1 -> 0.071 | G2: =PRODUCT(1+Renditen!G4)-1 -> 0.0944 | H2: =PRODUCT(1+Renditen!H4)-1 -> 0.0062631383 | I2: =PRODUCT(1+Renditen!I4)-1 -> 0.0034 | J2: =PRODUCT(1+Renditen!J4)-1 -> 0.020616561 | L2: 43466 | M2: =PRODUCT(1+Renditen!M4)-1 -> -0.0007548188 | N2: =PRODUCT(1+Renditen!N4)-1 -> 0.0032872105 | O2: =PRODUCT(1+Renditen!O4)-1 -> 0.0060515221 | P2: =PRODUCT(1+Renditen!P4)-1 -> 0.069611986 | Q2: =PRODUCT(1+Renditen!Q4)-1 -> 0.071190243 | R2: =PRODUCT(1+Renditen!R4)-1 -> 0.094508223 | S2: =PRODUCT(1+Renditen!S4)-1 -> 0.11255421 | T2: =PRODUCT(1+Renditen!T4)-1 -> 0.0032002074 | U2: =PRODUCT(1+Renditen!U4)-1 -> 0.10215547
A3: 43497 | B3: {=PRODUCT(1+Renditen!$B$4:B5)-1} -> -0.0013003 | C3: {=PRODUCT(1+Renditen!$C$4:C5)-1} -> 0.0058994 | D3: {=PRODUCT(1+Renditen!$D$4:D5)-1} -> 0.051842568 | E3: {=PRODUCT(1+Renditen!$E$4:E5)-1} -> 0.11517032 | F3: {=PRODUCT(1+Renditen!$F$4:F5)-1} -> 0.104201 | G3: {=PRODUCT(1+Renditen!$G$4:G5)-1} -> 0.10140416 | H3: {=PRODUCT(1+Renditen!$H$4:H5)-1} -> 0.0082400507 | I3: {=PRODUCT(1+Renditen!$I$4:I5)-1} -> 0.00681156 | J3: {=PRODUCT(1+Renditen!$J$4:J5)-1} -> 0.048874301 | L3: 43497 | M3: {=PRODUCT(1+Renditen!$M4:M5)-1} -> -0.0014188518 | N3: {=PRODUCT(1+Renditen!$N$4:N5)-1} -> 0.0042045716 | O3: {=PRODUCT(1+Renditen!$O$4:O5)-1} -> 0.0025400908 | P3: {=PRODUCT(1+Renditen!$P$4:P5)-1} -> 0.11540113 | Q3: {=PRODUCT(1+Renditen!$Q$4:Q5)-1} -> 0.10441492 | R3: {=PRODUCT(1+Renditen!$R$4:R5)-1} -> 0.10150174 | S3: {=PRODUCT(1+Renditen!$S$4:S5)-1} -> 0.14726836 | T3: {=PRODUCT(1+Renditen!$T$4:T5)-1} -> 0.0061103547 | U3: {=PRODUCT(1+Renditen!$U$4:U5)-1} -> 0.10404724
A4: 43525 | B4: {=PRODUCT(1+Renditen!$B$4:B6)-1} -> -0.0021991297 | C4: {=PRODUCT(1+Renditen!$C$4:C6)-1} -> 0.019579632 | D4: {=PRODUCT(1+Renditen!$D$4:D6)-1} -> 0.058656727 | E4: {=PRODUCT(1+Renditen!$E$4:E6)-1} -> 0.14304958 | F4: {=PRODUCT(1+Renditen!$F$4:F6)-1} -> 0.11954939 | G4: {=PRODUCT(1+Renditen!$G$4:G6)-1} -> 0.11043567 | H4: {=PRODUCT(1+Renditen!$H$4:H6)-1} -> -0.0030440951 | I4: {=PRODUCT(1+Renditen!$I$4:I6)-1} -> 0.010234719 | J4: {=PRODUCT(1+Renditen!$J$4:J6)-1} -> 0.047654526 | L4: 43525 | M4: {=PRODUCT(1+Renditen!$M$4:M6)-1} -> -0.0021416794 | N4: {=PRODUCT(1+Renditen!$N$4:N6)-1} -> 0.011161226 | O4: {=PRODUCT(1+Renditen!$O$4:O6)-1} -> 0.018691293 | P4: {=PRODUCT(1+Renditen!$P$4:P6)-1} -> 0.14355253 | Q4: {=PRODUCT(1+Renditen!$Q$4:Q6)-1} -> 0.11945262 | R4: {=PRODUCT(1+Renditen!$R$4:R6)-1} -> 0.11041102 | S4: {=PRODUCT(1+Renditen!$S$4:S6)-1} -> 0.15294967 | T4: {=PRODUCT(1+Renditen!$T$4:T6)-1} -> 0.010172455 | U4: {=PRODUCT(1+Renditen!$U$4:U6)-1} -> 0.14463426
A5: 43556 | B5: {=PRODUCT(1+Renditen!$B$4:B7)-1} -> -0.00040308816 | C5: {=PRODUCT(1+Renditen!$C$4:C7)-1} -> 0.015909145 | D5: {=PRODUCT(1+Renditen!$D$4:D7)-1} -> 0.059877865 | E5: {=PRODUCT(1+Renditen!$E$4:E7)-1} -> 0.19322945 | F5: {=PRODUCT(1+Renditen!$F$4:F7)-1} -> 0.16018904 | G5: {=PRODUCT(1+Renditen!$G$4:G7)-1} -> 0.15996111 | H5: {=PRODUCT(1+Renditen!$H$4:H7)-1} -> 0.018833542 | I5: {=PRODUCT(1+Renditen!$I$4:I7)-1} -> 0.013669517 | J5: {=PRODUCT(1+Renditen!$J$4:J7)-1} -> 0.043329246 | L5: 43556 | M5: {=PRODUCT(1+Renditen!$M$4:M7)-1} -> -0.0028074416 | N5: {=PRODUCT(1+Renditen!$N$4:N7)-1} -> 0.010090972 | O5: {=PRODUCT(1+Renditen!$O$4:O7)-1} -> 0.01398839 | P5: {=PRODUCT(1+Renditen!$P$4:P7)-1} -> 0.1938035 | Q5: {=PRODUCT(1+Renditen!$Q$4:Q7)-1} -> 0.16022052 | R5: {=PRODUCT(1+Renditen!$R$4:R7)-1} -> 0.16008737 | S5: {=PRODUCT(1+Renditen!$S$4:S7)-1} -> 0.25696479 | T5: {=PRODUCT(1+Renditen!$T$4:T7)-1} -> 0.013280227 | U5: {=PRODUCT(1+Renditen!$U$4:U7)-1} -> 0.13001605
A6: 43586 | B6: {=PRODUCT(1+Renditen!$B$4:B8)-1} -> -0.0018025238 | C6: {=PRODUCT(1+Renditen!$C$4:C8)-1} -> 0.030944601 | D6: {=PRODUCT(1+Renditen!$D$4:D8)-1} -> 0.05721276 | E6: {=PRODUCT(1+Renditen!$E$4:E8)-1} -> 0.17389914 | F6: {=PRODUCT(1+Renditen!$F$4:F8)-1} -> 0.090461676 | G6: {=PRODUCT(1+Renditen!$G$4:G8)-1} -> 0.062524372 | H6: {=PRODUCT(1+Renditen!$H$4:H8)-1} -> 0.0056947131 | I6: {=PRODUCT(1+Renditen!$I$4:I8)-1} -> 0.017115994 | J6: {=PRODUCT(1+Renditen!$J$4:J8)-1} -> 0.017756171 | L6: 43586 | M6: {=PRODUCT(1+Renditen!$M$4:M8)-1} -> -0.0034835794 | N6: {=PRODUCT(1+Renditen!$N$4:N8)-1} -> 0.01720052 | O6: {=PRODUCT(1+Renditen!$O$4:O8)-1} -> 0.02895398 | P6: {=PRODUCT(1+Renditen!$P$4:P8)-1} -> 0.17441196 | Q6: {=PRODUCT(1+Renditen!$Q$4:Q8)-1} -> 0.090887259 | R6: {=PRODUCT(1+Renditen!$R$4:R8)-1} -> 0.062023809 | S6: {=PRODUCT(1+Renditen!$S$4:S8)-1} -> 0.19070294 | T6: {=PRODUCT(1+Renditen!$T$4:T8)-1} -> 0.017068859 | U6: {=PRODUCT(1+Renditen!$U$4:U8)-1} -> 0.12560193
A7: 43617 | B7: {=PRODUCT(1+Renditen!$B$4:B9)-1} -> -0.0069931507 | C7: {=PRODUCT(1+Renditen!$C$4:C9)-1} -> 0.035274568 | D7: {=PRODUCT(1+Renditen!$D$4:D9)-1} -> 0.089129758 | E7: {=PRODUCT(1+Renditen!$E$4:E9)-1} -> 0.21827252 | F7: {=PRODUCT(1+Renditen!$F$4:F9)-1} -> 0.15174562 | G7: {=PRODUCT(1+Renditen!$G$4:G9)-1} -> 0.093231327 | H7: {=PRODUCT(1+Renditen!$H$4:H9)-1} -> -0.0017401838 | I7: {=PRODUCT(1+Renditen!$I$4:I9)-1} -> 0.020574188 | J7: {=PRODUCT(1+Renditen!$J$4:J9)-1} -> 0.021415311 | L7: 43617 | M7: {=PRODUCT(1+Renditen!$M$4:M9)-1} -> -0.004134643 | N7: {=PRODUCT(1+Renditen!$N$4:N9)-1} -> 0.019111689 | O7: {=PRODUCT(1+Renditen!$O$4:O9)-1} -> 0.040375286 | P7: {=PRODUCT(1+Renditen!$P$4:P9)-1} -> 0.21844424 | Q7: {=PRODUCT(1+Renditen!$Q$4:Q9)-1} -> 0.15202436 | R7: {=PRODUCT(1+Renditen!$R$4:R9)-1} -> 0.093701693 | S7: {=PRODUCT(1+Renditen!$S$4:S9)-1} -> 0.245066 | T7: {=PRODUCT(1+Renditen!$T$4:T9)-1} -> 0.020616314 | U7: {=PRODUCT(1+Renditen!$U$4:U9)-1} -> 0.13460216
A8: 43647 | B8: {=PRODUCT(1+Renditen!$B$4:B10)-1} -> -0.0074896541 | C8: {=PRODUCT(1+Renditen!$C$4:C10)-1} -> 0.050907214 | D8: {=PRODUCT(1+Renditen!$D$4:D10)-1} -> 0.10078856 | E8: {=PRODUCT(1+Renditen!$E$4:E10)-1} -> 0.22728774 | F8: {=PRODUCT(1+Renditen!$F$4:F10)-1} -> 0.16303273 | G8: {=PRODUCT(1+Renditen!$G$4:G10)-1} -> 0.096073728 | H8: {=PRODUCT(1+Renditen!$H$4:H10)-1} -> 0.01328096 | I8: {=PRODUCT(1+Renditen!$I$4:I10)-1} -> 0.02404414 | J8: {=PRODUCT(1+Renditen!$J$4:J10)-1} -> 0.027960685 | L8: 43647 | M8: {=PRODUCT(1+Renditen!$M$4:M10)-1} -> -0.0048090515 | N8: {=PRODUCT(1+Renditen!$N$4:N10)-1} -> 0.027138598 | O8: {=PRODUCT(1+Renditen!$O$4:O10)-1} -> 0.045568254 | P8: {=PRODUCT(1+Renditen!$P$4:P10)-1} -> 0.22730177 | Q8: {=PRODUCT(1+Renditen!$Q$4:Q10)-1} -> 0.16338666 | R8: {=PRODUCT(1+Renditen!$R$4:R10)-1} -> 0.096948012 | S8: {=PRODUCT(1+Renditen!$S$4:S10)-1} -> 0.27866681 | T8: {=PRODUCT(1+Renditen!$T$4:T10)-1} -> 0.024589704 | U8: {=PRODUCT(1+Renditen!$U$4:U10)-1} -> 0.14457693
A9: 43678 | B9: {=PRODUCT(1+Renditen!$B$4:B11)-1} -> -0.0080851603 | C9: {=PRODUCT(1+Renditen!$C$4:C11)-1} -> 0.075708624 | D9: {=PRODUCT(1+Renditen!$D$4:D11)-1} -> 0.10547178 | E9: {=PRODUCT(1+Renditen!$E$4:E11)-1} -> 0.22691956 | F9: {=PRODUCT(1+Renditen!$F$4:F11)-1} -> 0.13686449 | G9: {=PRODUCT(1+Renditen!$G$4:G11)-1} -> 0.041050827 | H9: {=PRODUCT(1+Renditen!$H$4:H11)-1} -> 0.014014988 | I9: {=PRODUCT(1+Renditen!$I$4:I11)-1} -> 0.02752589 | J9: {=PRODUCT(1+Renditen!$J$4:J11)-1} -> 0.040091891 | L9: 43678 | M9: {=PRODUCT(1+Renditen!$M$4:M11)-1} -> -0.0055154512 | N9: {=PRODUCT(1+Renditen!$N$4:N11)-1} -> 0.035471294 | O9: {=PRODUCT(1+Renditen!$O$4:O11)-1} -> 0.072794663 | P9: {=PRODUCT(1+Renditen!$P$4:P11)-1} -> 0.22694266 | Q9: {=PRODUCT(1+Renditen!$Q$4:Q11)-1} -> 0.13736389 | R9: {=PRODUCT(1+Renditen!$R$4:R11)-1} -> 0.042885207 | S9: {=PRODUCT(1+Renditen!$S$4:S11)-1} -> 0.27732699 | T9: {=PRODUCT(1+Renditen!$T$4:T11)-1} -> 0.028426199 | U9: {=PRODUCT(1+Renditen!$U$4:U11)-1} -> 0.16544371
A10: 43709 | B10: {=PRODUCT(1+Renditen!$B$4:B12)-1} -> -0.0089778837 | C10: {=PRODUCT(1+Renditen!$C$4:C12)-1} -> 0.055162589 | D10: {=PRODUCT(1+Renditen!$D$4:D12)-1} -> 0.09671505 | E10: {=PRODUCT(1+Renditen!$E$4:E12)-1} -> 0.24434181 | F10: {=PRODUCT(1+Renditen!$F$4:F12)-1} -> 0.16119339 | G10: {=PRODUCT(1+Renditen!$G$4:G12)-1} -> 0.069263304 | H10: {=PRODUCT(1+Renditen!$H$4:H12)-1} -> 0.056632636 | I10: {=PRODUCT(1+Renditen!$I$4:I12)-1} -> 0.031019478 | J10: {=PRODUCT(1+Renditen!$J$4:J12)-1} -> 0.057540074 | L10: 43709 | M10: {=PRODUCT(1+Renditen!$M$4:M12)-1} -> -0.0062564359 | N10: {=PRODUCT(1+Renditen!$N$4:N12)-1} -> 0.024004281 | O10: {=PRODUCT(1+Renditen!$O$4:O12)-1} -> 0.063322315 | P10: {=PRODUCT(1+Renditen!$P$4:P12)-1} -> 0.24446138 | Q10: {=PRODUCT(1+Renditen!$Q$4:Q12)-1} -> 0.16187824 | R10: {=PRODUCT(1+Renditen!$R$4:R12)-1} -> 0.071063837 | S10: {=PRODUCT(1+Renditen!$S$4:S12)-1} -> 0.3151796 | T10: {=PRODUCT(1+Renditen!$T$4:T12)-1} -> 0.034519171 | U10: {=PRODUCT(1+Renditen!$U$4:U12)-1} -> 0.19473745
A11: 43739 | B11: {=PRODUCT(1+Renditen!$B$4:B13)-1} -> -0.0096715992 | C11: {=PRODUCT(1+Renditen!$C$4:C13)-1} -> 0.037963439 | D11: {=PRODUCT(1+Renditen!$D$4:D13)-1} -> 0.096748866 | E11: {=PRODUCT(1+Renditen!$E$4:E13)-1} -> 0.25491872 | F11: {=PRODUCT(1+Renditen!$F$4:F13)-1} -> 0.18070144 | G11: {=PRODUCT(1+Renditen!$G$4:G13)-1} -> 0.10369358 | H11: {=PRODUCT(1+Renditen!$H$4:H13)-1} -> 0.045263852 | I11: {=PRODUCT(1+Renditen!$I$4:I13)-1} -> 0.034524945 | J11: {=PRODUCT(1+Renditen!$J$4:J13)-1} -> 0.06227003 | L11: 43739 | M11: {=PRODUCT(1+Renditen!$M$4:M13)-1} -> -0.0070527568 | N11: {=PRODUCT(1+Renditen!$N$4:N13)-1} -> 0.015977372 | O11: {=PRODUCT(1+Renditen!$O$4:O13)-1} -> 0.056092294 | P11: {=PRODUCT(1+Renditen!$P$4:P13)-1} -> 0.25503303 | Q11: {=PRODUCT(1+Renditen!$Q$4:Q13)-1} -> 0.1814653 | R11: {=PRODUCT(1+Renditen!$R$4:R13)-1} -> 0.10458588 | S11: {=PRODUCT(1+Renditen!$S$4:S13)-1} -> 0.34001355 | T11: {=PRODUCT(1+Renditen!$T$4:T13)-1} -> 0.038193783 | U11: {=PRODUCT(1+Renditen!$U$4:U13)-1} -> 0.21503096
A12: 43770 | B12: {=PRODUCT(1+Renditen!$B$4:B14)-1} -> -0.010067731 | C12: {=PRODUCT(1+Renditen!$C$4:C14)-1} -> 0.046267147 | D12: {=PRODUCT(1+Renditen!$D$4:D14)-1} -> 0.090291912 | E12: {=PRODUCT(1+Renditen!$E$4:E14)-1} -> 0.28942898 | F12: {=PRODUCT(1+Renditen!$F$4:F14)-1} -> 0.21635863 | G12: {=PRODUCT(1+Renditen!$G$4:G14)-1} -> 0.11605495 | H12: {=PRODUCT(1+Renditen!$H$4:H14)-1} -> 0.058537628 | I12: {=PRODUCT(1+Renditen!$I$4:I14)-1} -> 0.038042329 | J12: {=PRODUCT(1+Renditen!$J$4:J14)-1} -> 0.059454519 | L12: 43770 | M12: {=PRODUCT(1+Renditen!$M$4:M14)-1} -> -0.0078196803 | N12: {=PRODUCT(1+Renditen!$N$4:N14)-1} -> 0.019876156 | O12: {=PRODUCT(1+Renditen!$O$4:O14)-1} -> 0.049437294 | P12: {=PRODUCT(1+Renditen!$P$4:P14)-1} -> 0.28952519 | Q12: {=PRODUCT(1+Renditen!$Q$4:Q14)-1} -> 0.21722104 | R12: {=PRODUCT(1+Renditen!$R$4:R14)-1} -> 0.11714998 | S12: {=PRODUCT(1+Renditen!$S$4:S14)-1} -> 0.38990756 | T12: {=PRODUCT(1+Renditen!$T$4:T14)-1} -> 0.042130333 | U12: {=PRODUCT(1+Renditen!$U$4:U14)-1} -> 0.20304976
A13: 43800 | B13: {=PRODUCT(1+Renditen!$B$4:B15)-1} -> -0.013631487 | C13: {=PRODUCT(1+Renditen!$C$4:C15)-1} -> 0.034235074 | D13: {=PRODUCT(1+Renditen!$D$4:D15)-1} -> 0.10967048 | E13: {=PRODUCT(1+Renditen!$E$4:E15)-1} -> 0.30580473 | F13: {=PRODUCT(1+Renditen!$F$4:F15)-1} -> 0.24080743 | G13: {=PRODUCT(1+Renditen!$G$4:G15)-1} -> 0.16248284 | H13: {=PRODUCT(1+Renditen!$H$4:H15)-1} -> 0.021651899 | I13: {=PRODUCT(1+Renditen!$I$4:I15)-1} -> 0.054754811 | J13: {=PRODUCT(1+Renditen!$J$4:J15)-1} -> 0.057068336 | L13: 43800 | M13: {=PRODUCT(1+Renditen!$M$4:M15)-1} -> -0.0085528834 | N13: {=PRODUCT(1+Renditen!$N$4:N15)-1} -> 0.013989756 | O13: {=PRODUCT(1+Renditen!$O$4:O15)-1} -> 0.040211025 | P13: {=PRODUCT(1+Renditen!$P$4:P15)-1} -> 0.3059432 | Q13: {=PRODUCT(1+Renditen!$Q$4:Q15)-1} -> 0.2419494 | R13: {=PRODUCT(1+Renditen!$R$4:R15)-1} -> 0.16325593 | S13: {=PRODUCT(1+Renditen!$S$4:S15)-1} -> 0.40111168 | T13: {=PRODUCT(1+Renditen!$T$4:T15)-1} -> 0.051823123 | U13: {=PRODUCT(1+Renditen!$U$4:U15)-1} -> 0.19892227
A14: 43831 | B14: {=PRODUCT(1+Renditen!$B$4:B16)-1} -> -0.014815129 | C14: {=PRODUCT(1+Renditen!$C$4:C16)-1} -> 0.05709167 | D14: {=PRODUCT(1+Renditen!$D$4:D16)-1} -> 0.12344826 | E14: {=PRODUCT(1+Renditen!$E$4:E16)-1} -> 0.30919982 | F14: {=PRODUCT(1+Renditen!$F$4:F16)-1} -> 0.23472748 | G14: {=PRODUCT(1+Renditen!$G$4:G16)-1} -> 0.10005751 | H14: {=PRODUCT(1+Renditen!$H$4:H16)-1} -> 0.017273504 | I14: {=PRODUCT(1+Renditen!$I$4:I16)-1} -> 0.058235502 | J14: {=PRODUCT(1+Renditen!$J$4:J16)-1} -> 0.067379658 | L14: 43831 | M14: {=PRODUCT(1+Renditen!$M$4:M16)-1} -> -0.0092584185 | N14: {=PRODUCT(1+Renditen!$N$4:N16)-1} -> 0.024004281 | O14: {=PRODUCT(1+Renditen!$O$4:O16)-1} -> 0.061381517 | P14: {=PRODUCT(1+Renditen!$P$4:P16)-1} -> 0.3093501 | Q14: {=PRODUCT(1+Renditen!$Q$4:Q16)-1} -> 0.2363833 | R14: {=PRODUCT(1+Renditen!$R$4:R16)-1} -> 0.10456412 | S14: {=PRODUCT(1+Renditen!$S$4:S16)-1} -> 0.42361451 | T14: {=PRODUCT(1+Renditen!$T$4:T16)-1} -> 0.05523912 | U14: {=PRODUCT(1+Renditen!$U$4:U16)-1} -> 0.21256593
